Watching for file changes with StatReloader
Starting new HTTPS connection (1): api.deepseek.com:443
https://api.deepseek.com:443 "POST /v1/chat/completions HTTP/1.1" 400 114
DeepSeek API HTTP error: 400 Client Error: Bad Request for url: https://api.deepseek.com/v1/chat/completions, Status: 400, Response: {"error":{"message":"Model Not Exist","type":"invalid_request_error","param":null,"code":"invalid_request_error"}}
Internal Server Error: /api/chat/
C:\Users\Nazmul\Desktop\chatbot\api\views.py changed, reloading.
Watching for file changes with StatReloader
Watching for file changes with StatReloader
Unauthorized: /api/chat/history/
Unauthorized: /api/token/refresh/
Starting new HTTPS connection (1): api.deepseek.com:443
https://api.deepseek.com:443 "POST /v1/chat/completions HTTP/1.1" 400 114
DeepSeek API HTTP error: 400 Client Error: Bad Request for url: https://api.deepseek.com/v1/chat/completions, Status: 400, Response: {"error":{"message":"Model Not Exist","type":"invalid_request_error","param":null,"code":"invalid_request_error"}}
Internal Server Error: /api/chat/
Starting new HTTPS connection (1): api.deepseek.com:443
https://api.deepseek.com:443 "POST /v1/chat/completions HTTP/1.1" 400 114
DeepSeek API HTTP error: 400 Client Error: Bad Request for url: https://api.deepseek.com/v1/chat/completions, Status: 400, Response: {"error":{"message":"Model Not Exist","type":"invalid_request_error","param":null,"code":"invalid_request_error"}}
Internal Server Error: /api/chat/
C:\Users\Nazmul\Desktop\chatbot\api\views.py changed, reloading.
Watching for file changes with StatReloader
C:\Users\Nazmul\Desktop\chatbot\project\settings.py changed, reloading.
Watching for file changes with StatReloader
C:\Users\Nazmul\Desktop\chatbot\project\settings.py changed, reloading.
Watching for file changes with StatReloader
Unauthorized: /api/chat/history/
Unauthorized: /api/token/refresh/
Starting new HTTPS connection (1): api.deepseek.com:443
https://api.deepseek.com:443 "POST /v1/chat/completions HTTP/1.1" 402 111
DeepSeek API HTTP error: 402 Client Error: Payment Required for url: https://api.deepseek.com/v1/chat/completions, Status: 402, Response: {"error":{"message":"Insufficient Balance","type":"unknown_error","param":null,"code":"invalid_request_error"}}
Internal Server Error: /api/chat/
Starting new HTTPS connection (1): api.deepseek.com:443
https://api.deepseek.com:443 "POST /v1/chat/completions HTTP/1.1" 402 111
DeepSeek API HTTP error: 402 Client Error: Payment Required for url: https://api.deepseek.com/v1/chat/completions, Status: 402, Response: {"error":{"message":"Insufficient Balance","type":"unknown_error","param":null,"code":"invalid_request_error"}}
Internal Server Error: /api/chat/
C:\Users\Nazmul\Desktop\chatbot\api\views.py changed, reloading.
Watching for file changes with StatReloader
Starting new HTTPS connection (1): jsonplaceholder.typicode.com:443
https://jsonplaceholder.typicode.com:443 "POST /posts HTTP/1.1" 201 78
JSONPlaceholder API response saved for user: nazmul
Starting new HTTPS connection (1): jsonplaceholder.typicode.com:443
https://jsonplaceholder.typicode.com:443 "POST /posts HTTP/1.1" 201 94
JSONPlaceholder API response saved for user: nazmul
Starting new HTTPS connection (1): jsonplaceholder.typicode.com:443
https://jsonplaceholder.typicode.com:443 "POST /posts HTTP/1.1" 201 84
JSONPlaceholder API response saved for user: nazmul
Starting new HTTPS connection (1): jsonplaceholder.typicode.com:443
https://jsonplaceholder.typicode.com:443 "POST /posts HTTP/1.1" 201 81
JSONPlaceholder API response saved for user: nazmul
Starting new HTTPS connection (1): jsonplaceholder.typicode.com:443
https://jsonplaceholder.typicode.com:443 "POST /posts HTTP/1.1" 201 103
JSONPlaceholder API response saved for user: nazmul
Successfully imported extension module "markdown.extensions.toc".
Successfully loaded extension "markdown.extensions.toc.TocExtension".
Method Not Allowed: /api/register/
Successfully imported extension module "markdown.extensions.toc".
Successfully loaded extension "markdown.extensions.toc.TocExtension".
Method Not Allowed: /api/token/
Successfully imported extension module "markdown.extensions.toc".
Successfully loaded extension "markdown.extensions.toc.TocExtension".
Unauthorized: /api/chat/
Unauthorized: /api/chat/history/
Unauthorized: /api/chat/history/
Successfully imported extension module "markdown.extensions.toc".
Successfully loaded extension "markdown.extensions.toc.TocExtension".
Successfully imported extension module "markdown.extensions.toc".
Successfully loaded extension "markdown.extensions.toc.TocExtension".
Method Not Allowed: /api/register/
Successfully imported extension module "markdown.extensions.toc".
Successfully loaded extension "markdown.extensions.toc.TocExtension".
Bad Request: /api/register/
Sending JSONPlaceholder API request with prompt: hfai
Starting new HTTPS connection (1): jsonplaceholder.typicode.com:443
https://jsonplaceholder.typicode.com:443 "POST /posts HTTP/1.1" 201 76
Raw JSONPlaceholder API response: {
  "title": "Chatbot Query",
  "body": "hfai",
  "userId": 1,
  "id": 101
}
JSONPlaceholder API response saved for user: nazmul
Successfully imported extension module "markdown.extensions.toc".
Successfully loaded extension "markdown.extensions.toc.TocExtension".
Method Not Allowed: /api/token/
Watching for file changes with StatReloader
Sending JSONPlaceholder API request with prompt: hai
Starting new HTTPS connection (1): jsonplaceholder.typicode.com:443
https://jsonplaceholder.typicode.com:443 "POST /posts HTTP/1.1" 201 75
Raw JSONPlaceholder API response: {
  "title": "Chatbot Query",
  "body": "hai",
  "userId": 1,
  "id": 101
}
JSONPlaceholder API response saved for user: nazmul
Sending JSONPlaceholder API request with prompt: hello
Starting new HTTPS connection (1): jsonplaceholder.typicode.com:443
https://jsonplaceholder.typicode.com:443 "POST /posts HTTP/1.1" 201 77
Raw JSONPlaceholder API response: {
  "title": "Chatbot Query",
  "body": "hello",
  "userId": 1,
  "id": 101
}
JSONPlaceholder API response saved for user: nazmul
C:\Users\Nazmul\Desktop\chatbot\project\settings.py changed, reloading.
Watching for file changes with StatReloader
C:\Users\Nazmul\Desktop\chatbot\api\views.py changed, reloading.
Watching for file changes with StatReloader
Watching for file changes with StatReloader
Internal Server Error: /api/chat/
Traceback (most recent call last):
  File "C:\Users\Nazmul\Desktop\chatbot\api\views.py", line 68, in post
    response = GEMINI_MODEL.generate_content(user_query)
               ^^^^^^^^^^^^^^^^^^^^^^^^^^^^^^^^^^^^^^^^^
  File "C:\Users\Nazmul\AppData\Local\Programs\Python\Python311\Lib\site-packages\google\generativeai\generative_models.py", line 331, in generate_content
    response = self._client.generate_content(
               ^^^^^^^^^^^^^^^^^^^^^^^^^^^^^^
  File "C:\Users\Nazmul\AppData\Local\Programs\Python\Python311\Lib\site-packages\google\ai\generativelanguage_v1beta\services\generative_service\client.py", line 835, in generate_content
    response = rpc(
               ^^^^
  File "C:\Users\Nazmul\AppData\Local\Programs\Python\Python311\Lib\site-packages\google\api_core\gapic_v1\method.py", line 131, in __call__
    return wrapped_func(*args, **kwargs)
           ^^^^^^^^^^^^^^^^^^^^^^^^^^^^^
  File "C:\Users\Nazmul\AppData\Local\Programs\Python\Python311\Lib\site-packages\google\api_core\retry\retry_unary.py", line 294, in retry_wrapped_func
    return retry_target(
           ^^^^^^^^^^^^^
  File "C:\Users\Nazmul\AppData\Local\Programs\Python\Python311\Lib\site-packages\google\api_core\retry\retry_unary.py", line 156, in retry_target
    next_sleep = _retry_error_helper(
                 ^^^^^^^^^^^^^^^^^^^^
  File "C:\Users\Nazmul\AppData\Local\Programs\Python\Python311\Lib\site-packages\google\api_core\retry\retry_base.py", line 214, in _retry_error_helper
    raise final_exc from source_exc
  File "C:\Users\Nazmul\AppData\Local\Programs\Python\Python311\Lib\site-packages\google\api_core\retry\retry_unary.py", line 147, in retry_target
    result = target()
             ^^^^^^^^
  File "C:\Users\Nazmul\AppData\Local\Programs\Python\Python311\Lib\site-packages\google\api_core\timeout.py", line 130, in func_with_timeout
    return func(*args, **kwargs)
           ^^^^^^^^^^^^^^^^^^^^^
  File "C:\Users\Nazmul\AppData\Local\Programs\Python\Python311\Lib\site-packages\google\api_core\grpc_helpers.py", line 78, in error_remapped_callable
    raise exceptions.from_grpc_error(exc) from exc
google.api_core.exceptions.NotFound: 404 models/gemini-pro is not found for API version v1beta, or is not supported for generateContent. Call ListModels to see the list of available models and their supported methods.

During handling of the above exception, another exception occurred:

Traceback (most recent call last):
  File "C:\Users\Nazmul\AppData\Local\Programs\Python\Python311\Lib\site-packages\django\core\handlers\exception.py", line 55, in inner
    response = get_response(request)
               ^^^^^^^^^^^^^^^^^^^^^
  File "C:\Users\Nazmul\AppData\Local\Programs\Python\Python311\Lib\site-packages\django\core\handlers\base.py", line 197, in _get_response
    response = wrapped_callback(request, *callback_args, **callback_kwargs)
               ^^^^^^^^^^^^^^^^^^^^^^^^^^^^^^^^^^^^^^^^^^^^^^^^^^^^^^^^^^^^
  File "C:\Users\Nazmul\AppData\Local\Programs\Python\Python311\Lib\site-packages\django\views\decorators\csrf.py", line 65, in _view_wrapper
    return view_func(request, *args, **kwargs)
           ^^^^^^^^^^^^^^^^^^^^^^^^^^^^^^^^^^^
  File "C:\Users\Nazmul\AppData\Local\Programs\Python\Python311\Lib\site-packages\django\views\generic\base.py", line 105, in view
    return self.dispatch(request, *args, **kwargs)
           ^^^^^^^^^^^^^^^^^^^^^^^^^^^^^^^^^^^^^^^
  File "C:\Users\Nazmul\AppData\Local\Programs\Python\Python311\Lib\site-packages\rest_framework\views.py", line 515, in dispatch
    response = self.handle_exception(exc)
               ^^^^^^^^^^^^^^^^^^^^^^^^^^
  File "C:\Users\Nazmul\AppData\Local\Programs\Python\Python311\Lib\site-packages\rest_framework\views.py", line 475, in handle_exception
    self.raise_uncaught_exception(exc)
  File "C:\Users\Nazmul\AppData\Local\Programs\Python\Python311\Lib\site-packages\rest_framework\views.py", line 486, in raise_uncaught_exception
    raise exc
  File "C:\Users\Nazmul\AppData\Local\Programs\Python\Python311\Lib\site-packages\rest_framework\views.py", line 512, in dispatch
    response = handler(request, *args, **kwargs)
               ^^^^^^^^^^^^^^^^^^^^^^^^^^^^^^^^^
  File "C:\Users\Nazmul\Desktop\chatbot\api\views.py", line 94, in post
    except genai.types.APIError as e:
           ^^^^^^^^^^^^^^^^^^^^
AttributeError: module 'google.generativeai.types' has no attribute 'APIError'
C:\Users\Nazmul\Desktop\chatbot\api\urls.py changed, reloading.
Watching for file changes with StatReloader
Internal Server Error: /api/chat/
Traceback (most recent call last):
  File "C:\Users\Nazmul\Desktop\chatbot\api\views.py", line 68, in post
    response = GEMINI_MODEL.generate_content(user_query)
               ^^^^^^^^^^^^^^^^^^^^^^^^^^^^^^^^^^^^^^^^^
  File "C:\Users\Nazmul\AppData\Local\Programs\Python\Python311\Lib\site-packages\google\generativeai\generative_models.py", line 331, in generate_content
    response = self._client.generate_content(
               ^^^^^^^^^^^^^^^^^^^^^^^^^^^^^^
  File "C:\Users\Nazmul\AppData\Local\Programs\Python\Python311\Lib\site-packages\google\ai\generativelanguage_v1beta\services\generative_service\client.py", line 835, in generate_content
    response = rpc(
               ^^^^
  File "C:\Users\Nazmul\AppData\Local\Programs\Python\Python311\Lib\site-packages\google\api_core\gapic_v1\method.py", line 131, in __call__
    return wrapped_func(*args, **kwargs)
           ^^^^^^^^^^^^^^^^^^^^^^^^^^^^^
  File "C:\Users\Nazmul\AppData\Local\Programs\Python\Python311\Lib\site-packages\google\api_core\retry\retry_unary.py", line 294, in retry_wrapped_func
    return retry_target(
           ^^^^^^^^^^^^^
  File "C:\Users\Nazmul\AppData\Local\Programs\Python\Python311\Lib\site-packages\google\api_core\retry\retry_unary.py", line 156, in retry_target
    next_sleep = _retry_error_helper(
                 ^^^^^^^^^^^^^^^^^^^^
  File "C:\Users\Nazmul\AppData\Local\Programs\Python\Python311\Lib\site-packages\google\api_core\retry\retry_base.py", line 214, in _retry_error_helper
    raise final_exc from source_exc
  File "C:\Users\Nazmul\AppData\Local\Programs\Python\Python311\Lib\site-packages\google\api_core\retry\retry_unary.py", line 147, in retry_target
    result = target()
             ^^^^^^^^
  File "C:\Users\Nazmul\AppData\Local\Programs\Python\Python311\Lib\site-packages\google\api_core\timeout.py", line 130, in func_with_timeout
    return func(*args, **kwargs)
           ^^^^^^^^^^^^^^^^^^^^^
  File "C:\Users\Nazmul\AppData\Local\Programs\Python\Python311\Lib\site-packages\google\api_core\grpc_helpers.py", line 78, in error_remapped_callable
    raise exceptions.from_grpc_error(exc) from exc
google.api_core.exceptions.NotFound: 404 models/gemini-pro is not found for API version v1beta, or is not supported for generateContent. Call ListModels to see the list of available models and their supported methods.

During handling of the above exception, another exception occurred:

Traceback (most recent call last):
  File "C:\Users\Nazmul\AppData\Local\Programs\Python\Python311\Lib\site-packages\django\core\handlers\exception.py", line 55, in inner
    response = get_response(request)
               ^^^^^^^^^^^^^^^^^^^^^
  File "C:\Users\Nazmul\AppData\Local\Programs\Python\Python311\Lib\site-packages\django\core\handlers\base.py", line 197, in _get_response
    response = wrapped_callback(request, *callback_args, **callback_kwargs)
               ^^^^^^^^^^^^^^^^^^^^^^^^^^^^^^^^^^^^^^^^^^^^^^^^^^^^^^^^^^^^
  File "C:\Users\Nazmul\AppData\Local\Programs\Python\Python311\Lib\site-packages\django\views\decorators\csrf.py", line 65, in _view_wrapper
    return view_func(request, *args, **kwargs)
           ^^^^^^^^^^^^^^^^^^^^^^^^^^^^^^^^^^^
  File "C:\Users\Nazmul\AppData\Local\Programs\Python\Python311\Lib\site-packages\django\views\generic\base.py", line 105, in view
    return self.dispatch(request, *args, **kwargs)
           ^^^^^^^^^^^^^^^^^^^^^^^^^^^^^^^^^^^^^^^
  File "C:\Users\Nazmul\AppData\Local\Programs\Python\Python311\Lib\site-packages\rest_framework\views.py", line 515, in dispatch
    response = self.handle_exception(exc)
               ^^^^^^^^^^^^^^^^^^^^^^^^^^
  File "C:\Users\Nazmul\AppData\Local\Programs\Python\Python311\Lib\site-packages\rest_framework\views.py", line 475, in handle_exception
    self.raise_uncaught_exception(exc)
  File "C:\Users\Nazmul\AppData\Local\Programs\Python\Python311\Lib\site-packages\rest_framework\views.py", line 486, in raise_uncaught_exception
    raise exc
  File "C:\Users\Nazmul\AppData\Local\Programs\Python\Python311\Lib\site-packages\rest_framework\views.py", line 512, in dispatch
    response = handler(request, *args, **kwargs)
               ^^^^^^^^^^^^^^^^^^^^^^^^^^^^^^^^^
  File "C:\Users\Nazmul\Desktop\chatbot\api\views.py", line 94, in post
    except genai.types.APIError as e:
           ^^^^^^^^^^^^^^^^^^^^
AttributeError: module 'google.generativeai.types' has no attribute 'APIError'
C:\Users\Nazmul\Desktop\chatbot\api\views.py changed, reloading.
Watching for file changes with StatReloader
Internal Server Error: /api/chat/
Traceback (most recent call last):
  File "C:\Users\Nazmul\Desktop\chatbot\api\views.py", line 66, in post
    response = GEMINI_MODEL.generate_content(user_query)
               ^^^^^^^^^^^^^^^^^^^^^^^^^^^^^^^^^^^^^^^^^
  File "C:\Users\Nazmul\AppData\Local\Programs\Python\Python311\Lib\site-packages\google\generativeai\generative_models.py", line 331, in generate_content
    response = self._client.generate_content(
               ^^^^^^^^^^^^^^^^^^^^^^^^^^^^^^
  File "C:\Users\Nazmul\AppData\Local\Programs\Python\Python311\Lib\site-packages\google\ai\generativelanguage_v1beta\services\generative_service\client.py", line 835, in generate_content
    response = rpc(
               ^^^^
  File "C:\Users\Nazmul\AppData\Local\Programs\Python\Python311\Lib\site-packages\google\api_core\gapic_v1\method.py", line 131, in __call__
    return wrapped_func(*args, **kwargs)
           ^^^^^^^^^^^^^^^^^^^^^^^^^^^^^
  File "C:\Users\Nazmul\AppData\Local\Programs\Python\Python311\Lib\site-packages\google\api_core\retry\retry_unary.py", line 294, in retry_wrapped_func
    return retry_target(
           ^^^^^^^^^^^^^
  File "C:\Users\Nazmul\AppData\Local\Programs\Python\Python311\Lib\site-packages\google\api_core\retry\retry_unary.py", line 156, in retry_target
    next_sleep = _retry_error_helper(
                 ^^^^^^^^^^^^^^^^^^^^
  File "C:\Users\Nazmul\AppData\Local\Programs\Python\Python311\Lib\site-packages\google\api_core\retry\retry_base.py", line 214, in _retry_error_helper
    raise final_exc from source_exc
  File "C:\Users\Nazmul\AppData\Local\Programs\Python\Python311\Lib\site-packages\google\api_core\retry\retry_unary.py", line 147, in retry_target
    result = target()
             ^^^^^^^^
  File "C:\Users\Nazmul\AppData\Local\Programs\Python\Python311\Lib\site-packages\google\api_core\timeout.py", line 130, in func_with_timeout
    return func(*args, **kwargs)
           ^^^^^^^^^^^^^^^^^^^^^
  File "C:\Users\Nazmul\AppData\Local\Programs\Python\Python311\Lib\site-packages\google\api_core\grpc_helpers.py", line 78, in error_remapped_callable
    raise exceptions.from_grpc_error(exc) from exc
google.api_core.exceptions.NotFound: 404 models/gemini-pro is not found for API version v1beta, or is not supported for generateContent. Call ListModels to see the list of available models and their supported methods.

During handling of the above exception, another exception occurred:

Traceback (most recent call last):
  File "C:\Users\Nazmul\AppData\Local\Programs\Python\Python311\Lib\site-packages\django\core\handlers\exception.py", line 55, in inner
    response = get_response(request)
               ^^^^^^^^^^^^^^^^^^^^^
  File "C:\Users\Nazmul\AppData\Local\Programs\Python\Python311\Lib\site-packages\django\core\handlers\base.py", line 197, in _get_response
    response = wrapped_callback(request, *callback_args, **callback_kwargs)
               ^^^^^^^^^^^^^^^^^^^^^^^^^^^^^^^^^^^^^^^^^^^^^^^^^^^^^^^^^^^^
  File "C:\Users\Nazmul\AppData\Local\Programs\Python\Python311\Lib\site-packages\django\views\decorators\csrf.py", line 65, in _view_wrapper
    return view_func(request, *args, **kwargs)
           ^^^^^^^^^^^^^^^^^^^^^^^^^^^^^^^^^^^
  File "C:\Users\Nazmul\AppData\Local\Programs\Python\Python311\Lib\site-packages\django\views\generic\base.py", line 105, in view
    return self.dispatch(request, *args, **kwargs)
           ^^^^^^^^^^^^^^^^^^^^^^^^^^^^^^^^^^^^^^^
  File "C:\Users\Nazmul\AppData\Local\Programs\Python\Python311\Lib\site-packages\rest_framework\views.py", line 515, in dispatch
    response = self.handle_exception(exc)
               ^^^^^^^^^^^^^^^^^^^^^^^^^^
  File "C:\Users\Nazmul\AppData\Local\Programs\Python\Python311\Lib\site-packages\rest_framework\views.py", line 475, in handle_exception
    self.raise_uncaught_exception(exc)
  File "C:\Users\Nazmul\AppData\Local\Programs\Python\Python311\Lib\site-packages\rest_framework\views.py", line 486, in raise_uncaught_exception
    raise exc
  File "C:\Users\Nazmul\AppData\Local\Programs\Python\Python311\Lib\site-packages\rest_framework\views.py", line 512, in dispatch
    response = handler(request, *args, **kwargs)
               ^^^^^^^^^^^^^^^^^^^^^^^^^^^^^^^^^
  File "C:\Users\Nazmul\Desktop\chatbot\api\views.py", line 92, in post
    except genai.types.APIError as e:
           ^^^^^^^^^^^^^^^^^^^^
AttributeError: module 'google.generativeai.types' has no attribute 'APIError'
Internal Server Error: /api/chat/
Traceback (most recent call last):
  File "C:\Users\Nazmul\Desktop\chatbot\api\views.py", line 66, in post
    response = GEMINI_MODEL.generate_content(user_query)
               ^^^^^^^^^^^^^^^^^^^^^^^^^^^^^^^^^^^^^^^^^
  File "C:\Users\Nazmul\AppData\Local\Programs\Python\Python311\Lib\site-packages\google\generativeai\generative_models.py", line 331, in generate_content
    response = self._client.generate_content(
               ^^^^^^^^^^^^^^^^^^^^^^^^^^^^^^
  File "C:\Users\Nazmul\AppData\Local\Programs\Python\Python311\Lib\site-packages\google\ai\generativelanguage_v1beta\services\generative_service\client.py", line 835, in generate_content
    response = rpc(
               ^^^^
  File "C:\Users\Nazmul\AppData\Local\Programs\Python\Python311\Lib\site-packages\google\api_core\gapic_v1\method.py", line 131, in __call__
    return wrapped_func(*args, **kwargs)
           ^^^^^^^^^^^^^^^^^^^^^^^^^^^^^
  File "C:\Users\Nazmul\AppData\Local\Programs\Python\Python311\Lib\site-packages\google\api_core\retry\retry_unary.py", line 294, in retry_wrapped_func
    return retry_target(
           ^^^^^^^^^^^^^
  File "C:\Users\Nazmul\AppData\Local\Programs\Python\Python311\Lib\site-packages\google\api_core\retry\retry_unary.py", line 156, in retry_target
    next_sleep = _retry_error_helper(
                 ^^^^^^^^^^^^^^^^^^^^
  File "C:\Users\Nazmul\AppData\Local\Programs\Python\Python311\Lib\site-packages\google\api_core\retry\retry_base.py", line 214, in _retry_error_helper
    raise final_exc from source_exc
  File "C:\Users\Nazmul\AppData\Local\Programs\Python\Python311\Lib\site-packages\google\api_core\retry\retry_unary.py", line 147, in retry_target
    result = target()
             ^^^^^^^^
  File "C:\Users\Nazmul\AppData\Local\Programs\Python\Python311\Lib\site-packages\google\api_core\timeout.py", line 130, in func_with_timeout
    return func(*args, **kwargs)
           ^^^^^^^^^^^^^^^^^^^^^
  File "C:\Users\Nazmul\AppData\Local\Programs\Python\Python311\Lib\site-packages\google\api_core\grpc_helpers.py", line 78, in error_remapped_callable
    raise exceptions.from_grpc_error(exc) from exc
google.api_core.exceptions.NotFound: 404 models/gemini-pro is not found for API version v1beta, or is not supported for generateContent. Call ListModels to see the list of available models and their supported methods.

During handling of the above exception, another exception occurred:

Traceback (most recent call last):
  File "C:\Users\Nazmul\AppData\Local\Programs\Python\Python311\Lib\site-packages\django\core\handlers\exception.py", line 55, in inner
    response = get_response(request)
               ^^^^^^^^^^^^^^^^^^^^^
  File "C:\Users\Nazmul\AppData\Local\Programs\Python\Python311\Lib\site-packages\django\core\handlers\base.py", line 197, in _get_response
    response = wrapped_callback(request, *callback_args, **callback_kwargs)
               ^^^^^^^^^^^^^^^^^^^^^^^^^^^^^^^^^^^^^^^^^^^^^^^^^^^^^^^^^^^^
  File "C:\Users\Nazmul\AppData\Local\Programs\Python\Python311\Lib\site-packages\django\views\decorators\csrf.py", line 65, in _view_wrapper
    return view_func(request, *args, **kwargs)
           ^^^^^^^^^^^^^^^^^^^^^^^^^^^^^^^^^^^
  File "C:\Users\Nazmul\AppData\Local\Programs\Python\Python311\Lib\site-packages\django\views\generic\base.py", line 105, in view
    return self.dispatch(request, *args, **kwargs)
           ^^^^^^^^^^^^^^^^^^^^^^^^^^^^^^^^^^^^^^^
  File "C:\Users\Nazmul\AppData\Local\Programs\Python\Python311\Lib\site-packages\rest_framework\views.py", line 515, in dispatch
    response = self.handle_exception(exc)
               ^^^^^^^^^^^^^^^^^^^^^^^^^^
  File "C:\Users\Nazmul\AppData\Local\Programs\Python\Python311\Lib\site-packages\rest_framework\views.py", line 475, in handle_exception
    self.raise_uncaught_exception(exc)
  File "C:\Users\Nazmul\AppData\Local\Programs\Python\Python311\Lib\site-packages\rest_framework\views.py", line 486, in raise_uncaught_exception
    raise exc
  File "C:\Users\Nazmul\AppData\Local\Programs\Python\Python311\Lib\site-packages\rest_framework\views.py", line 512, in dispatch
    response = handler(request, *args, **kwargs)
               ^^^^^^^^^^^^^^^^^^^^^^^^^^^^^^^^^
  File "C:\Users\Nazmul\Desktop\chatbot\api\views.py", line 92, in post
    except genai.types.APIError as e:
           ^^^^^^^^^^^^^^^^^^^^
AttributeError: module 'google.generativeai.types' has no attribute 'APIError'
Watching for file changes with StatReloader
Sending query to Gemini API: ha
Internal Server Error: /api/chat/
Traceback (most recent call last):
  File "C:\Users\Nazmul\Desktop\chatbot\api\views.py", line 66, in post
    response = GEMINI_MODEL.generate_content(user_query)
               ^^^^^^^^^^^^^^^^^^^^^^^^^^^^^^^^^^^^^^^^^
  File "C:\Users\Nazmul\AppData\Local\Programs\Python\Python311\Lib\site-packages\google\generativeai\generative_models.py", line 331, in generate_content
    response = self._client.generate_content(
               ^^^^^^^^^^^^^^^^^^^^^^^^^^^^^^
  File "C:\Users\Nazmul\AppData\Local\Programs\Python\Python311\Lib\site-packages\google\ai\generativelanguage_v1beta\services\generative_service\client.py", line 835, in generate_content
    response = rpc(
               ^^^^
  File "C:\Users\Nazmul\AppData\Local\Programs\Python\Python311\Lib\site-packages\google\api_core\gapic_v1\method.py", line 131, in __call__
    return wrapped_func(*args, **kwargs)
           ^^^^^^^^^^^^^^^^^^^^^^^^^^^^^
  File "C:\Users\Nazmul\AppData\Local\Programs\Python\Python311\Lib\site-packages\google\api_core\retry\retry_unary.py", line 294, in retry_wrapped_func
    return retry_target(
           ^^^^^^^^^^^^^
  File "C:\Users\Nazmul\AppData\Local\Programs\Python\Python311\Lib\site-packages\google\api_core\retry\retry_unary.py", line 156, in retry_target
    next_sleep = _retry_error_helper(
                 ^^^^^^^^^^^^^^^^^^^^
  File "C:\Users\Nazmul\AppData\Local\Programs\Python\Python311\Lib\site-packages\google\api_core\retry\retry_base.py", line 214, in _retry_error_helper
    raise final_exc from source_exc
  File "C:\Users\Nazmul\AppData\Local\Programs\Python\Python311\Lib\site-packages\google\api_core\retry\retry_unary.py", line 147, in retry_target
    result = target()
             ^^^^^^^^
  File "C:\Users\Nazmul\AppData\Local\Programs\Python\Python311\Lib\site-packages\google\api_core\timeout.py", line 130, in func_with_timeout
    return func(*args, **kwargs)
           ^^^^^^^^^^^^^^^^^^^^^
  File "C:\Users\Nazmul\AppData\Local\Programs\Python\Python311\Lib\site-packages\google\api_core\grpc_helpers.py", line 78, in error_remapped_callable
    raise exceptions.from_grpc_error(exc) from exc
google.api_core.exceptions.NotFound: 404 models/gemini-pro is not found for API version v1beta, or is not supported for generateContent. Call ListModels to see the list of available models and their supported methods.

During handling of the above exception, another exception occurred:

Traceback (most recent call last):
  File "C:\Users\Nazmul\AppData\Local\Programs\Python\Python311\Lib\site-packages\django\core\handlers\exception.py", line 55, in inner
    response = get_response(request)
               ^^^^^^^^^^^^^^^^^^^^^
  File "C:\Users\Nazmul\AppData\Local\Programs\Python\Python311\Lib\site-packages\django\core\handlers\base.py", line 197, in _get_response
    response = wrapped_callback(request, *callback_args, **callback_kwargs)
               ^^^^^^^^^^^^^^^^^^^^^^^^^^^^^^^^^^^^^^^^^^^^^^^^^^^^^^^^^^^^
  File "C:\Users\Nazmul\AppData\Local\Programs\Python\Python311\Lib\site-packages\django\views\decorators\csrf.py", line 65, in _view_wrapper
    return view_func(request, *args, **kwargs)
           ^^^^^^^^^^^^^^^^^^^^^^^^^^^^^^^^^^^
  File "C:\Users\Nazmul\AppData\Local\Programs\Python\Python311\Lib\site-packages\django\views\generic\base.py", line 105, in view
    return self.dispatch(request, *args, **kwargs)
           ^^^^^^^^^^^^^^^^^^^^^^^^^^^^^^^^^^^^^^^
  File "C:\Users\Nazmul\AppData\Local\Programs\Python\Python311\Lib\site-packages\rest_framework\views.py", line 515, in dispatch
    response = self.handle_exception(exc)
               ^^^^^^^^^^^^^^^^^^^^^^^^^^
  File "C:\Users\Nazmul\AppData\Local\Programs\Python\Python311\Lib\site-packages\rest_framework\views.py", line 475, in handle_exception
    self.raise_uncaught_exception(exc)
  File "C:\Users\Nazmul\AppData\Local\Programs\Python\Python311\Lib\site-packages\rest_framework\views.py", line 486, in raise_uncaught_exception
    raise exc
  File "C:\Users\Nazmul\AppData\Local\Programs\Python\Python311\Lib\site-packages\rest_framework\views.py", line 512, in dispatch
    response = handler(request, *args, **kwargs)
               ^^^^^^^^^^^^^^^^^^^^^^^^^^^^^^^^^
  File "C:\Users\Nazmul\Desktop\chatbot\api\views.py", line 92, in post
    except genai.types.APIError as e:
           ^^^^^^^^^^^^^^^^^^^^
AttributeError: module 'google.generativeai.types' has no attribute 'APIError'
Unauthorized: /api/chat/
Successfully imported extension module "markdown.extensions.toc".
Successfully loaded extension "markdown.extensions.toc.TocExtension".
Method Not Allowed: /api/token/
Successfully imported extension module "markdown.extensions.toc".
Successfully loaded extension "markdown.extensions.toc.TocExtension".
Unauthorized: /api/chat/
Sending query to Gemini API: rer
Internal Server Error: /api/chat/
Traceback (most recent call last):
  File "C:\Users\Nazmul\Desktop\chatbot\api\views.py", line 66, in post
    response = GEMINI_MODEL.generate_content(user_query)
               ^^^^^^^^^^^^^^^^^^^^^^^^^^^^^^^^^^^^^^^^^
  File "C:\Users\Nazmul\AppData\Local\Programs\Python\Python311\Lib\site-packages\google\generativeai\generative_models.py", line 331, in generate_content
    response = self._client.generate_content(
               ^^^^^^^^^^^^^^^^^^^^^^^^^^^^^^
  File "C:\Users\Nazmul\AppData\Local\Programs\Python\Python311\Lib\site-packages\google\ai\generativelanguage_v1beta\services\generative_service\client.py", line 835, in generate_content
    response = rpc(
               ^^^^
  File "C:\Users\Nazmul\AppData\Local\Programs\Python\Python311\Lib\site-packages\google\api_core\gapic_v1\method.py", line 131, in __call__
    return wrapped_func(*args, **kwargs)
           ^^^^^^^^^^^^^^^^^^^^^^^^^^^^^
  File "C:\Users\Nazmul\AppData\Local\Programs\Python\Python311\Lib\site-packages\google\api_core\retry\retry_unary.py", line 294, in retry_wrapped_func
    return retry_target(
           ^^^^^^^^^^^^^
  File "C:\Users\Nazmul\AppData\Local\Programs\Python\Python311\Lib\site-packages\google\api_core\retry\retry_unary.py", line 156, in retry_target
    next_sleep = _retry_error_helper(
                 ^^^^^^^^^^^^^^^^^^^^
  File "C:\Users\Nazmul\AppData\Local\Programs\Python\Python311\Lib\site-packages\google\api_core\retry\retry_base.py", line 214, in _retry_error_helper
    raise final_exc from source_exc
  File "C:\Users\Nazmul\AppData\Local\Programs\Python\Python311\Lib\site-packages\google\api_core\retry\retry_unary.py", line 147, in retry_target
    result = target()
             ^^^^^^^^
  File "C:\Users\Nazmul\AppData\Local\Programs\Python\Python311\Lib\site-packages\google\api_core\timeout.py", line 130, in func_with_timeout
    return func(*args, **kwargs)
           ^^^^^^^^^^^^^^^^^^^^^
  File "C:\Users\Nazmul\AppData\Local\Programs\Python\Python311\Lib\site-packages\google\api_core\grpc_helpers.py", line 78, in error_remapped_callable
    raise exceptions.from_grpc_error(exc) from exc
google.api_core.exceptions.NotFound: 404 models/gemini-pro is not found for API version v1beta, or is not supported for generateContent. Call ListModels to see the list of available models and their supported methods.

During handling of the above exception, another exception occurred:

Traceback (most recent call last):
  File "C:\Users\Nazmul\AppData\Local\Programs\Python\Python311\Lib\site-packages\django\core\handlers\exception.py", line 55, in inner
    response = get_response(request)
               ^^^^^^^^^^^^^^^^^^^^^
  File "C:\Users\Nazmul\AppData\Local\Programs\Python\Python311\Lib\site-packages\django\core\handlers\base.py", line 197, in _get_response
    response = wrapped_callback(request, *callback_args, **callback_kwargs)
               ^^^^^^^^^^^^^^^^^^^^^^^^^^^^^^^^^^^^^^^^^^^^^^^^^^^^^^^^^^^^
  File "C:\Users\Nazmul\AppData\Local\Programs\Python\Python311\Lib\site-packages\django\views\decorators\csrf.py", line 65, in _view_wrapper
    return view_func(request, *args, **kwargs)
           ^^^^^^^^^^^^^^^^^^^^^^^^^^^^^^^^^^^
  File "C:\Users\Nazmul\AppData\Local\Programs\Python\Python311\Lib\site-packages\django\views\generic\base.py", line 105, in view
    return self.dispatch(request, *args, **kwargs)
           ^^^^^^^^^^^^^^^^^^^^^^^^^^^^^^^^^^^^^^^
  File "C:\Users\Nazmul\AppData\Local\Programs\Python\Python311\Lib\site-packages\rest_framework\views.py", line 515, in dispatch
    response = self.handle_exception(exc)
               ^^^^^^^^^^^^^^^^^^^^^^^^^^
  File "C:\Users\Nazmul\AppData\Local\Programs\Python\Python311\Lib\site-packages\rest_framework\views.py", line 475, in handle_exception
    self.raise_uncaught_exception(exc)
  File "C:\Users\Nazmul\AppData\Local\Programs\Python\Python311\Lib\site-packages\rest_framework\views.py", line 486, in raise_uncaught_exception
    raise exc
  File "C:\Users\Nazmul\AppData\Local\Programs\Python\Python311\Lib\site-packages\rest_framework\views.py", line 512, in dispatch
    response = handler(request, *args, **kwargs)
               ^^^^^^^^^^^^^^^^^^^^^^^^^^^^^^^^^
  File "C:\Users\Nazmul\Desktop\chatbot\api\views.py", line 92, in post
    except genai.types.APIError as e:
           ^^^^^^^^^^^^^^^^^^^^
AttributeError: module 'google.generativeai.types' has no attribute 'APIError'
C:\Users\Nazmul\Desktop\chatbot\project\settings.py changed, reloading.
Watching for file changes with StatReloader
Watching for file changes with StatReloader
Unauthorized: /api/chat/history/
Internal Server Error: /api/token/refresh/
Traceback (most recent call last):
  File "C:\Users\Nazmul\AppData\Local\Programs\Python\Python311\Lib\site-packages\django\core\handlers\exception.py", line 55, in inner
    response = get_response(request)
               ^^^^^^^^^^^^^^^^^^^^^
  File "C:\Users\Nazmul\AppData\Local\Programs\Python\Python311\Lib\site-packages\django\core\handlers\base.py", line 197, in _get_response
    response = wrapped_callback(request, *callback_args, **callback_kwargs)
               ^^^^^^^^^^^^^^^^^^^^^^^^^^^^^^^^^^^^^^^^^^^^^^^^^^^^^^^^^^^^
  File "C:\Users\Nazmul\AppData\Local\Programs\Python\Python311\Lib\site-packages\django\views\decorators\csrf.py", line 65, in _view_wrapper
    return view_func(request, *args, **kwargs)
           ^^^^^^^^^^^^^^^^^^^^^^^^^^^^^^^^^^^
  File "C:\Users\Nazmul\AppData\Local\Programs\Python\Python311\Lib\site-packages\django\views\generic\base.py", line 105, in view
    return self.dispatch(request, *args, **kwargs)
           ^^^^^^^^^^^^^^^^^^^^^^^^^^^^^^^^^^^^^^^
  File "C:\Users\Nazmul\AppData\Local\Programs\Python\Python311\Lib\site-packages\rest_framework\views.py", line 515, in dispatch
    response = self.handle_exception(exc)
               ^^^^^^^^^^^^^^^^^^^^^^^^^^
  File "C:\Users\Nazmul\AppData\Local\Programs\Python\Python311\Lib\site-packages\rest_framework\views.py", line 475, in handle_exception
    self.raise_uncaught_exception(exc)
  File "C:\Users\Nazmul\AppData\Local\Programs\Python\Python311\Lib\site-packages\rest_framework\views.py", line 486, in raise_uncaught_exception
    raise exc
  File "C:\Users\Nazmul\AppData\Local\Programs\Python\Python311\Lib\site-packages\rest_framework\views.py", line 512, in dispatch
    response = handler(request, *args, **kwargs)
               ^^^^^^^^^^^^^^^^^^^^^^^^^^^^^^^^^
  File "C:\Users\Nazmul\AppData\Local\Programs\Python\Python311\Lib\site-packages\rest_framework_simplejwt\views.py", line 44, in post
    serializer.is_valid(raise_exception=True)
  File "C:\Users\Nazmul\AppData\Local\Programs\Python\Python311\Lib\site-packages\rest_framework\serializers.py", line 225, in is_valid
    self._validated_data = self.run_validation(self.initial_data)
                           ^^^^^^^^^^^^^^^^^^^^^^^^^^^^^^^^^^^^^^
  File "C:\Users\Nazmul\AppData\Local\Programs\Python\Python311\Lib\site-packages\rest_framework\serializers.py", line 447, in run_validation
    value = self.validate(value)
            ^^^^^^^^^^^^^^^^^^^^
  File "C:\Users\Nazmul\AppData\Local\Programs\Python\Python311\Lib\site-packages\rest_framework_simplejwt\serializers.py", line 141, in validate
    refresh.outstand()
  File "C:\Users\Nazmul\AppData\Local\Programs\Python\Python311\Lib\site-packages\rest_framework_simplejwt\tokens.py", line 222, in outstand
    return OutstandingToken.objects.get_or_create(
           ^^^^^^^^^^^^^^^^^^^^^^^^
AttributeError: type object 'OutstandingToken' has no attribute 'objects'
Sending query to Gemini API: cdf
Internal Server Error: /api/chat/
Traceback (most recent call last):
  File "C:\Users\Nazmul\Desktop\chatbot\api\views.py", line 66, in post
    response = GEMINI_MODEL.generate_content(user_query)
               ^^^^^^^^^^^^^^^^^^^^^^^^^^^^^^^^^^^^^^^^^
  File "C:\Users\Nazmul\AppData\Local\Programs\Python\Python311\Lib\site-packages\google\generativeai\generative_models.py", line 331, in generate_content
    response = self._client.generate_content(
               ^^^^^^^^^^^^^^^^^^^^^^^^^^^^^^
  File "C:\Users\Nazmul\AppData\Local\Programs\Python\Python311\Lib\site-packages\google\ai\generativelanguage_v1beta\services\generative_service\client.py", line 835, in generate_content
    response = rpc(
               ^^^^
  File "C:\Users\Nazmul\AppData\Local\Programs\Python\Python311\Lib\site-packages\google\api_core\gapic_v1\method.py", line 131, in __call__
    return wrapped_func(*args, **kwargs)
           ^^^^^^^^^^^^^^^^^^^^^^^^^^^^^
  File "C:\Users\Nazmul\AppData\Local\Programs\Python\Python311\Lib\site-packages\google\api_core\retry\retry_unary.py", line 294, in retry_wrapped_func
    return retry_target(
           ^^^^^^^^^^^^^
  File "C:\Users\Nazmul\AppData\Local\Programs\Python\Python311\Lib\site-packages\google\api_core\retry\retry_unary.py", line 156, in retry_target
    next_sleep = _retry_error_helper(
                 ^^^^^^^^^^^^^^^^^^^^
  File "C:\Users\Nazmul\AppData\Local\Programs\Python\Python311\Lib\site-packages\google\api_core\retry\retry_base.py", line 214, in _retry_error_helper
    raise final_exc from source_exc
  File "C:\Users\Nazmul\AppData\Local\Programs\Python\Python311\Lib\site-packages\google\api_core\retry\retry_unary.py", line 147, in retry_target
    result = target()
             ^^^^^^^^
  File "C:\Users\Nazmul\AppData\Local\Programs\Python\Python311\Lib\site-packages\google\api_core\timeout.py", line 130, in func_with_timeout
    return func(*args, **kwargs)
           ^^^^^^^^^^^^^^^^^^^^^
  File "C:\Users\Nazmul\AppData\Local\Programs\Python\Python311\Lib\site-packages\google\api_core\grpc_helpers.py", line 78, in error_remapped_callable
    raise exceptions.from_grpc_error(exc) from exc
google.api_core.exceptions.NotFound: 404 models/gemini-pro is not found for API version v1beta, or is not supported for generateContent. Call ListModels to see the list of available models and their supported methods.

During handling of the above exception, another exception occurred:

Traceback (most recent call last):
  File "C:\Users\Nazmul\AppData\Local\Programs\Python\Python311\Lib\site-packages\django\core\handlers\exception.py", line 55, in inner
    response = get_response(request)
               ^^^^^^^^^^^^^^^^^^^^^
  File "C:\Users\Nazmul\AppData\Local\Programs\Python\Python311\Lib\site-packages\django\core\handlers\base.py", line 197, in _get_response
    response = wrapped_callback(request, *callback_args, **callback_kwargs)
               ^^^^^^^^^^^^^^^^^^^^^^^^^^^^^^^^^^^^^^^^^^^^^^^^^^^^^^^^^^^^
  File "C:\Users\Nazmul\AppData\Local\Programs\Python\Python311\Lib\site-packages\django\views\decorators\csrf.py", line 65, in _view_wrapper
    return view_func(request, *args, **kwargs)
           ^^^^^^^^^^^^^^^^^^^^^^^^^^^^^^^^^^^
  File "C:\Users\Nazmul\AppData\Local\Programs\Python\Python311\Lib\site-packages\django\views\generic\base.py", line 105, in view
    return self.dispatch(request, *args, **kwargs)
           ^^^^^^^^^^^^^^^^^^^^^^^^^^^^^^^^^^^^^^^
  File "C:\Users\Nazmul\AppData\Local\Programs\Python\Python311\Lib\site-packages\rest_framework\views.py", line 515, in dispatch
    response = self.handle_exception(exc)
               ^^^^^^^^^^^^^^^^^^^^^^^^^^
  File "C:\Users\Nazmul\AppData\Local\Programs\Python\Python311\Lib\site-packages\rest_framework\views.py", line 475, in handle_exception
    self.raise_uncaught_exception(exc)
  File "C:\Users\Nazmul\AppData\Local\Programs\Python\Python311\Lib\site-packages\rest_framework\views.py", line 486, in raise_uncaught_exception
    raise exc
  File "C:\Users\Nazmul\AppData\Local\Programs\Python\Python311\Lib\site-packages\rest_framework\views.py", line 512, in dispatch
    response = handler(request, *args, **kwargs)
               ^^^^^^^^^^^^^^^^^^^^^^^^^^^^^^^^^
  File "C:\Users\Nazmul\Desktop\chatbot\api\views.py", line 92, in post
    except genai.types.APIError as e:
           ^^^^^^^^^^^^^^^^^^^^
AttributeError: module 'google.generativeai.types' has no attribute 'APIError'
Sending query to Gemini API: fdfd
Internal Server Error: /api/chat/
Traceback (most recent call last):
  File "C:\Users\Nazmul\Desktop\chatbot\api\views.py", line 66, in post
    response = GEMINI_MODEL.generate_content(user_query)
               ^^^^^^^^^^^^^^^^^^^^^^^^^^^^^^^^^^^^^^^^^
  File "C:\Users\Nazmul\AppData\Local\Programs\Python\Python311\Lib\site-packages\google\generativeai\generative_models.py", line 331, in generate_content
    response = self._client.generate_content(
               ^^^^^^^^^^^^^^^^^^^^^^^^^^^^^^
  File "C:\Users\Nazmul\AppData\Local\Programs\Python\Python311\Lib\site-packages\google\ai\generativelanguage_v1beta\services\generative_service\client.py", line 835, in generate_content
    response = rpc(
               ^^^^
  File "C:\Users\Nazmul\AppData\Local\Programs\Python\Python311\Lib\site-packages\google\api_core\gapic_v1\method.py", line 131, in __call__
    return wrapped_func(*args, **kwargs)
           ^^^^^^^^^^^^^^^^^^^^^^^^^^^^^
  File "C:\Users\Nazmul\AppData\Local\Programs\Python\Python311\Lib\site-packages\google\api_core\retry\retry_unary.py", line 294, in retry_wrapped_func
    return retry_target(
           ^^^^^^^^^^^^^
  File "C:\Users\Nazmul\AppData\Local\Programs\Python\Python311\Lib\site-packages\google\api_core\retry\retry_unary.py", line 156, in retry_target
    next_sleep = _retry_error_helper(
                 ^^^^^^^^^^^^^^^^^^^^
  File "C:\Users\Nazmul\AppData\Local\Programs\Python\Python311\Lib\site-packages\google\api_core\retry\retry_base.py", line 214, in _retry_error_helper
    raise final_exc from source_exc
  File "C:\Users\Nazmul\AppData\Local\Programs\Python\Python311\Lib\site-packages\google\api_core\retry\retry_unary.py", line 147, in retry_target
    result = target()
             ^^^^^^^^
  File "C:\Users\Nazmul\AppData\Local\Programs\Python\Python311\Lib\site-packages\google\api_core\timeout.py", line 130, in func_with_timeout
    return func(*args, **kwargs)
           ^^^^^^^^^^^^^^^^^^^^^
  File "C:\Users\Nazmul\AppData\Local\Programs\Python\Python311\Lib\site-packages\google\api_core\grpc_helpers.py", line 78, in error_remapped_callable
    raise exceptions.from_grpc_error(exc) from exc
google.api_core.exceptions.NotFound: 404 models/gemini-pro is not found for API version v1beta, or is not supported for generateContent. Call ListModels to see the list of available models and their supported methods.

During handling of the above exception, another exception occurred:

Traceback (most recent call last):
  File "C:\Users\Nazmul\AppData\Local\Programs\Python\Python311\Lib\site-packages\django\core\handlers\exception.py", line 55, in inner
    response = get_response(request)
               ^^^^^^^^^^^^^^^^^^^^^
  File "C:\Users\Nazmul\AppData\Local\Programs\Python\Python311\Lib\site-packages\django\core\handlers\base.py", line 197, in _get_response
    response = wrapped_callback(request, *callback_args, **callback_kwargs)
               ^^^^^^^^^^^^^^^^^^^^^^^^^^^^^^^^^^^^^^^^^^^^^^^^^^^^^^^^^^^^
  File "C:\Users\Nazmul\AppData\Local\Programs\Python\Python311\Lib\site-packages\django\views\decorators\csrf.py", line 65, in _view_wrapper
    return view_func(request, *args, **kwargs)
           ^^^^^^^^^^^^^^^^^^^^^^^^^^^^^^^^^^^
  File "C:\Users\Nazmul\AppData\Local\Programs\Python\Python311\Lib\site-packages\django\views\generic\base.py", line 105, in view
    return self.dispatch(request, *args, **kwargs)
           ^^^^^^^^^^^^^^^^^^^^^^^^^^^^^^^^^^^^^^^
  File "C:\Users\Nazmul\AppData\Local\Programs\Python\Python311\Lib\site-packages\rest_framework\views.py", line 515, in dispatch
    response = self.handle_exception(exc)
               ^^^^^^^^^^^^^^^^^^^^^^^^^^
  File "C:\Users\Nazmul\AppData\Local\Programs\Python\Python311\Lib\site-packages\rest_framework\views.py", line 475, in handle_exception
    self.raise_uncaught_exception(exc)
  File "C:\Users\Nazmul\AppData\Local\Programs\Python\Python311\Lib\site-packages\rest_framework\views.py", line 486, in raise_uncaught_exception
    raise exc
  File "C:\Users\Nazmul\AppData\Local\Programs\Python\Python311\Lib\site-packages\rest_framework\views.py", line 512, in dispatch
    response = handler(request, *args, **kwargs)
               ^^^^^^^^^^^^^^^^^^^^^^^^^^^^^^^^^
  File "C:\Users\Nazmul\Desktop\chatbot\api\views.py", line 92, in post
    except genai.types.APIError as e:
           ^^^^^^^^^^^^^^^^^^^^
AttributeError: module 'google.generativeai.types' has no attribute 'APIError'
Watching for file changes with StatReloader
Watching for file changes with StatReloader
Sending query to Gemini API: python
Internal Server Error: /api/chat/
Traceback (most recent call last):
  File "C:\Users\Nazmul\Desktop\chatbot\api\views.py", line 66, in post
    response = GEMINI_MODEL.generate_content(user_query)
               ^^^^^^^^^^^^^^^^^^^^^^^^^^^^^^^^^^^^^^^^^
  File "C:\Users\Nazmul\AppData\Local\Programs\Python\Python311\Lib\site-packages\google\generativeai\generative_models.py", line 331, in generate_content
    response = self._client.generate_content(
               ^^^^^^^^^^^^^^^^^^^^^^^^^^^^^^
  File "C:\Users\Nazmul\AppData\Local\Programs\Python\Python311\Lib\site-packages\google\ai\generativelanguage_v1beta\services\generative_service\client.py", line 835, in generate_content
    response = rpc(
               ^^^^
  File "C:\Users\Nazmul\AppData\Local\Programs\Python\Python311\Lib\site-packages\google\api_core\gapic_v1\method.py", line 131, in __call__
    return wrapped_func(*args, **kwargs)
           ^^^^^^^^^^^^^^^^^^^^^^^^^^^^^
  File "C:\Users\Nazmul\AppData\Local\Programs\Python\Python311\Lib\site-packages\google\api_core\retry\retry_unary.py", line 294, in retry_wrapped_func
    return retry_target(
           ^^^^^^^^^^^^^
  File "C:\Users\Nazmul\AppData\Local\Programs\Python\Python311\Lib\site-packages\google\api_core\retry\retry_unary.py", line 156, in retry_target
    next_sleep = _retry_error_helper(
                 ^^^^^^^^^^^^^^^^^^^^
  File "C:\Users\Nazmul\AppData\Local\Programs\Python\Python311\Lib\site-packages\google\api_core\retry\retry_base.py", line 214, in _retry_error_helper
    raise final_exc from source_exc
  File "C:\Users\Nazmul\AppData\Local\Programs\Python\Python311\Lib\site-packages\google\api_core\retry\retry_unary.py", line 147, in retry_target
    result = target()
             ^^^^^^^^
  File "C:\Users\Nazmul\AppData\Local\Programs\Python\Python311\Lib\site-packages\google\api_core\timeout.py", line 130, in func_with_timeout
    return func(*args, **kwargs)
           ^^^^^^^^^^^^^^^^^^^^^
  File "C:\Users\Nazmul\AppData\Local\Programs\Python\Python311\Lib\site-packages\google\api_core\grpc_helpers.py", line 78, in error_remapped_callable
    raise exceptions.from_grpc_error(exc) from exc
google.api_core.exceptions.NotFound: 404 models/gemini-pro is not found for API version v1beta, or is not supported for generateContent. Call ListModels to see the list of available models and their supported methods.

During handling of the above exception, another exception occurred:

Traceback (most recent call last):
  File "C:\Users\Nazmul\AppData\Local\Programs\Python\Python311\Lib\site-packages\django\core\handlers\exception.py", line 55, in inner
    response = get_response(request)
               ^^^^^^^^^^^^^^^^^^^^^
  File "C:\Users\Nazmul\AppData\Local\Programs\Python\Python311\Lib\site-packages\django\core\handlers\base.py", line 197, in _get_response
    response = wrapped_callback(request, *callback_args, **callback_kwargs)
               ^^^^^^^^^^^^^^^^^^^^^^^^^^^^^^^^^^^^^^^^^^^^^^^^^^^^^^^^^^^^
  File "C:\Users\Nazmul\AppData\Local\Programs\Python\Python311\Lib\site-packages\django\views\decorators\csrf.py", line 65, in _view_wrapper
    return view_func(request, *args, **kwargs)
           ^^^^^^^^^^^^^^^^^^^^^^^^^^^^^^^^^^^
  File "C:\Users\Nazmul\AppData\Local\Programs\Python\Python311\Lib\site-packages\django\views\generic\base.py", line 105, in view
    return self.dispatch(request, *args, **kwargs)
           ^^^^^^^^^^^^^^^^^^^^^^^^^^^^^^^^^^^^^^^
  File "C:\Users\Nazmul\AppData\Local\Programs\Python\Python311\Lib\site-packages\rest_framework\views.py", line 515, in dispatch
    response = self.handle_exception(exc)
               ^^^^^^^^^^^^^^^^^^^^^^^^^^
  File "C:\Users\Nazmul\AppData\Local\Programs\Python\Python311\Lib\site-packages\rest_framework\views.py", line 475, in handle_exception
    self.raise_uncaught_exception(exc)
  File "C:\Users\Nazmul\AppData\Local\Programs\Python\Python311\Lib\site-packages\rest_framework\views.py", line 486, in raise_uncaught_exception
    raise exc
  File "C:\Users\Nazmul\AppData\Local\Programs\Python\Python311\Lib\site-packages\rest_framework\views.py", line 512, in dispatch
    response = handler(request, *args, **kwargs)
               ^^^^^^^^^^^^^^^^^^^^^^^^^^^^^^^^^
  File "C:\Users\Nazmul\Desktop\chatbot\api\views.py", line 92, in post
    except genai.types.APIError as e:
           ^^^^^^^^^^^^^^^^^^^^
AttributeError: module 'google.generativeai.types' has no attribute 'APIError'
Watching for file changes with StatReloader
Not Found: /favicon.ico
Unauthorized: /api/chat/history/
Internal Server Error: /api/token/refresh/
Traceback (most recent call last):
  File "C:\Users\Nazmul\AppData\Local\Programs\Python\Python311\Lib\site-packages\django\core\handlers\exception.py", line 55, in inner
    response = get_response(request)
               ^^^^^^^^^^^^^^^^^^^^^
  File "C:\Users\Nazmul\AppData\Local\Programs\Python\Python311\Lib\site-packages\django\core\handlers\base.py", line 197, in _get_response
    response = wrapped_callback(request, *callback_args, **callback_kwargs)
               ^^^^^^^^^^^^^^^^^^^^^^^^^^^^^^^^^^^^^^^^^^^^^^^^^^^^^^^^^^^^
  File "C:\Users\Nazmul\AppData\Local\Programs\Python\Python311\Lib\site-packages\django\views\decorators\csrf.py", line 65, in _view_wrapper
    return view_func(request, *args, **kwargs)
           ^^^^^^^^^^^^^^^^^^^^^^^^^^^^^^^^^^^
  File "C:\Users\Nazmul\AppData\Local\Programs\Python\Python311\Lib\site-packages\django\views\generic\base.py", line 105, in view
    return self.dispatch(request, *args, **kwargs)
           ^^^^^^^^^^^^^^^^^^^^^^^^^^^^^^^^^^^^^^^
  File "C:\Users\Nazmul\AppData\Local\Programs\Python\Python311\Lib\site-packages\rest_framework\views.py", line 515, in dispatch
    response = self.handle_exception(exc)
               ^^^^^^^^^^^^^^^^^^^^^^^^^^
  File "C:\Users\Nazmul\AppData\Local\Programs\Python\Python311\Lib\site-packages\rest_framework\views.py", line 475, in handle_exception
    self.raise_uncaught_exception(exc)
  File "C:\Users\Nazmul\AppData\Local\Programs\Python\Python311\Lib\site-packages\rest_framework\views.py", line 486, in raise_uncaught_exception
    raise exc
  File "C:\Users\Nazmul\AppData\Local\Programs\Python\Python311\Lib\site-packages\rest_framework\views.py", line 512, in dispatch
    response = handler(request, *args, **kwargs)
               ^^^^^^^^^^^^^^^^^^^^^^^^^^^^^^^^^
  File "C:\Users\Nazmul\AppData\Local\Programs\Python\Python311\Lib\site-packages\rest_framework_simplejwt\views.py", line 44, in post
    serializer.is_valid(raise_exception=True)
  File "C:\Users\Nazmul\AppData\Local\Programs\Python\Python311\Lib\site-packages\rest_framework\serializers.py", line 225, in is_valid
    self._validated_data = self.run_validation(self.initial_data)
                           ^^^^^^^^^^^^^^^^^^^^^^^^^^^^^^^^^^^^^^
  File "C:\Users\Nazmul\AppData\Local\Programs\Python\Python311\Lib\site-packages\rest_framework\serializers.py", line 447, in run_validation
    value = self.validate(value)
            ^^^^^^^^^^^^^^^^^^^^
  File "C:\Users\Nazmul\AppData\Local\Programs\Python\Python311\Lib\site-packages\rest_framework_simplejwt\serializers.py", line 141, in validate
    refresh.outstand()
  File "C:\Users\Nazmul\AppData\Local\Programs\Python\Python311\Lib\site-packages\rest_framework_simplejwt\tokens.py", line 222, in outstand
    return OutstandingToken.objects.get_or_create(
           ^^^^^^^^^^^^^^^^^^^^^^^^
AttributeError: type object 'OutstandingToken' has no attribute 'objects'
Sending query to Gemini API: hai
Internal Server Error: /api/chat/
Traceback (most recent call last):
  File "C:\Users\Nazmul\Desktop\chatbot\api\views.py", line 66, in post
    response = GEMINI_MODEL.generate_content(user_query)
               ^^^^^^^^^^^^^^^^^^^^^^^^^^^^^^^^^^^^^^^^^
  File "C:\Users\Nazmul\AppData\Local\Programs\Python\Python311\Lib\site-packages\google\generativeai\generative_models.py", line 331, in generate_content
    response = self._client.generate_content(
               ^^^^^^^^^^^^^^^^^^^^^^^^^^^^^^
  File "C:\Users\Nazmul\AppData\Local\Programs\Python\Python311\Lib\site-packages\google\ai\generativelanguage_v1beta\services\generative_service\client.py", line 835, in generate_content
    response = rpc(
               ^^^^
  File "C:\Users\Nazmul\AppData\Local\Programs\Python\Python311\Lib\site-packages\google\api_core\gapic_v1\method.py", line 131, in __call__
    return wrapped_func(*args, **kwargs)
           ^^^^^^^^^^^^^^^^^^^^^^^^^^^^^
  File "C:\Users\Nazmul\AppData\Local\Programs\Python\Python311\Lib\site-packages\google\api_core\retry\retry_unary.py", line 294, in retry_wrapped_func
    return retry_target(
           ^^^^^^^^^^^^^
  File "C:\Users\Nazmul\AppData\Local\Programs\Python\Python311\Lib\site-packages\google\api_core\retry\retry_unary.py", line 156, in retry_target
    next_sleep = _retry_error_helper(
                 ^^^^^^^^^^^^^^^^^^^^
  File "C:\Users\Nazmul\AppData\Local\Programs\Python\Python311\Lib\site-packages\google\api_core\retry\retry_base.py", line 214, in _retry_error_helper
    raise final_exc from source_exc
  File "C:\Users\Nazmul\AppData\Local\Programs\Python\Python311\Lib\site-packages\google\api_core\retry\retry_unary.py", line 147, in retry_target
    result = target()
             ^^^^^^^^
  File "C:\Users\Nazmul\AppData\Local\Programs\Python\Python311\Lib\site-packages\google\api_core\timeout.py", line 130, in func_with_timeout
    return func(*args, **kwargs)
           ^^^^^^^^^^^^^^^^^^^^^
  File "C:\Users\Nazmul\AppData\Local\Programs\Python\Python311\Lib\site-packages\google\api_core\grpc_helpers.py", line 78, in error_remapped_callable
    raise exceptions.from_grpc_error(exc) from exc
google.api_core.exceptions.NotFound: 404 models/gemini-pro is not found for API version v1beta, or is not supported for generateContent. Call ListModels to see the list of available models and their supported methods.

During handling of the above exception, another exception occurred:

Traceback (most recent call last):
  File "C:\Users\Nazmul\AppData\Local\Programs\Python\Python311\Lib\site-packages\django\core\handlers\exception.py", line 55, in inner
    response = get_response(request)
               ^^^^^^^^^^^^^^^^^^^^^
  File "C:\Users\Nazmul\AppData\Local\Programs\Python\Python311\Lib\site-packages\django\core\handlers\base.py", line 197, in _get_response
    response = wrapped_callback(request, *callback_args, **callback_kwargs)
               ^^^^^^^^^^^^^^^^^^^^^^^^^^^^^^^^^^^^^^^^^^^^^^^^^^^^^^^^^^^^
  File "C:\Users\Nazmul\AppData\Local\Programs\Python\Python311\Lib\site-packages\django\views\decorators\csrf.py", line 65, in _view_wrapper
    return view_func(request, *args, **kwargs)
           ^^^^^^^^^^^^^^^^^^^^^^^^^^^^^^^^^^^
  File "C:\Users\Nazmul\AppData\Local\Programs\Python\Python311\Lib\site-packages\django\views\generic\base.py", line 105, in view
    return self.dispatch(request, *args, **kwargs)
           ^^^^^^^^^^^^^^^^^^^^^^^^^^^^^^^^^^^^^^^
  File "C:\Users\Nazmul\AppData\Local\Programs\Python\Python311\Lib\site-packages\rest_framework\views.py", line 515, in dispatch
    response = self.handle_exception(exc)
               ^^^^^^^^^^^^^^^^^^^^^^^^^^
  File "C:\Users\Nazmul\AppData\Local\Programs\Python\Python311\Lib\site-packages\rest_framework\views.py", line 475, in handle_exception
    self.raise_uncaught_exception(exc)
  File "C:\Users\Nazmul\AppData\Local\Programs\Python\Python311\Lib\site-packages\rest_framework\views.py", line 486, in raise_uncaught_exception
    raise exc
  File "C:\Users\Nazmul\AppData\Local\Programs\Python\Python311\Lib\site-packages\rest_framework\views.py", line 512, in dispatch
    response = handler(request, *args, **kwargs)
               ^^^^^^^^^^^^^^^^^^^^^^^^^^^^^^^^^
  File "C:\Users\Nazmul\Desktop\chatbot\api\views.py", line 92, in post
    except genai.types.APIError as e:
           ^^^^^^^^^^^^^^^^^^^^
AttributeError: module 'google.generativeai.types' has no attribute 'APIError'
Unauthorized: /api/chat/
Unauthorized: /api/chat/
C:\Users\Nazmul\Desktop\chatbot\api\views.py changed, reloading.
Watching for file changes with StatReloader
Internal Server Error: /api/chat/
Traceback (most recent call last):
  File "C:\Users\Nazmul\Desktop\chatbot\api\views.py", line 66, in post
    response = GEMINI_MODEL.generate_content(user_query)
               ^^^^^^^^^^^^^^^^^^^^^^^^^^^^^^^^^^^^^^^^^
  File "C:\Users\Nazmul\AppData\Local\Programs\Python\Python311\Lib\site-packages\google\generativeai\generative_models.py", line 331, in generate_content
    response = self._client.generate_content(
               ^^^^^^^^^^^^^^^^^^^^^^^^^^^^^^
  File "C:\Users\Nazmul\AppData\Local\Programs\Python\Python311\Lib\site-packages\google\ai\generativelanguage_v1beta\services\generative_service\client.py", line 835, in generate_content
    response = rpc(
               ^^^^
  File "C:\Users\Nazmul\AppData\Local\Programs\Python\Python311\Lib\site-packages\google\api_core\gapic_v1\method.py", line 131, in __call__
    return wrapped_func(*args, **kwargs)
           ^^^^^^^^^^^^^^^^^^^^^^^^^^^^^
  File "C:\Users\Nazmul\AppData\Local\Programs\Python\Python311\Lib\site-packages\google\api_core\retry\retry_unary.py", line 294, in retry_wrapped_func
    return retry_target(
           ^^^^^^^^^^^^^
  File "C:\Users\Nazmul\AppData\Local\Programs\Python\Python311\Lib\site-packages\google\api_core\retry\retry_unary.py", line 156, in retry_target
    next_sleep = _retry_error_helper(
                 ^^^^^^^^^^^^^^^^^^^^
  File "C:\Users\Nazmul\AppData\Local\Programs\Python\Python311\Lib\site-packages\google\api_core\retry\retry_base.py", line 214, in _retry_error_helper
    raise final_exc from source_exc
  File "C:\Users\Nazmul\AppData\Local\Programs\Python\Python311\Lib\site-packages\google\api_core\retry\retry_unary.py", line 147, in retry_target
    result = target()
             ^^^^^^^^
  File "C:\Users\Nazmul\AppData\Local\Programs\Python\Python311\Lib\site-packages\google\api_core\timeout.py", line 130, in func_with_timeout
    return func(*args, **kwargs)
           ^^^^^^^^^^^^^^^^^^^^^
  File "C:\Users\Nazmul\AppData\Local\Programs\Python\Python311\Lib\site-packages\google\api_core\grpc_helpers.py", line 78, in error_remapped_callable
    raise exceptions.from_grpc_error(exc) from exc
google.api_core.exceptions.NotFound: 404 models/gemini-pro is not found for API version v1beta, or is not supported for generateContent. Call ListModels to see the list of available models and their supported methods.

During handling of the above exception, another exception occurred:

Traceback (most recent call last):
  File "C:\Users\Nazmul\AppData\Local\Programs\Python\Python311\Lib\site-packages\django\core\handlers\exception.py", line 55, in inner
    response = get_response(request)
               ^^^^^^^^^^^^^^^^^^^^^
  File "C:\Users\Nazmul\AppData\Local\Programs\Python\Python311\Lib\site-packages\django\core\handlers\base.py", line 197, in _get_response
    response = wrapped_callback(request, *callback_args, **callback_kwargs)
               ^^^^^^^^^^^^^^^^^^^^^^^^^^^^^^^^^^^^^^^^^^^^^^^^^^^^^^^^^^^^
  File "C:\Users\Nazmul\AppData\Local\Programs\Python\Python311\Lib\site-packages\django\views\decorators\csrf.py", line 65, in _view_wrapper
    return view_func(request, *args, **kwargs)
           ^^^^^^^^^^^^^^^^^^^^^^^^^^^^^^^^^^^
  File "C:\Users\Nazmul\AppData\Local\Programs\Python\Python311\Lib\site-packages\django\views\generic\base.py", line 105, in view
    return self.dispatch(request, *args, **kwargs)
           ^^^^^^^^^^^^^^^^^^^^^^^^^^^^^^^^^^^^^^^
  File "C:\Users\Nazmul\AppData\Local\Programs\Python\Python311\Lib\site-packages\rest_framework\views.py", line 515, in dispatch
    response = self.handle_exception(exc)
               ^^^^^^^^^^^^^^^^^^^^^^^^^^
  File "C:\Users\Nazmul\AppData\Local\Programs\Python\Python311\Lib\site-packages\rest_framework\views.py", line 475, in handle_exception
    self.raise_uncaught_exception(exc)
  File "C:\Users\Nazmul\AppData\Local\Programs\Python\Python311\Lib\site-packages\rest_framework\views.py", line 486, in raise_uncaught_exception
    raise exc
  File "C:\Users\Nazmul\AppData\Local\Programs\Python\Python311\Lib\site-packages\rest_framework\views.py", line 512, in dispatch
    response = handler(request, *args, **kwargs)
               ^^^^^^^^^^^^^^^^^^^^^^^^^^^^^^^^^
  File "C:\Users\Nazmul\Desktop\chatbot\api\views.py", line 94, in post
    except genai.APIError as e:
          ^^^^^^^^^^^^^^
AttributeError: module 'google.generativeai' has no attribute 'APIError'
C:\Users\Nazmul\Desktop\chatbot\api\views.py changed, reloading.
Watching for file changes with StatReloader
Gemini API Call Error: 404 models/gemini-pro is not found for API version v1beta, or is not supported for generateContent. Call ListModels to see the list of available models and their supported methods.
Traceback (most recent call last):
  File "C:\Users\Nazmul\Desktop\chatbot\api\views.py", line 62, in post
    response = GEMINI_MODEL.generate_content(user_query)
               ^^^^^^^^^^^^^^^^^^^^^^^^^^^^^^^^^^^^^^^^^
  File "C:\Users\Nazmul\AppData\Local\Programs\Python\Python311\Lib\site-packages\google\generativeai\generative_models.py", line 331, in generate_content
    response = self._client.generate_content(
               ^^^^^^^^^^^^^^^^^^^^^^^^^^^^^^
  File "C:\Users\Nazmul\AppData\Local\Programs\Python\Python311\Lib\site-packages\google\ai\generativelanguage_v1beta\services\generative_service\client.py", line 835, in generate_content
    response = rpc(
               ^^^^
  File "C:\Users\Nazmul\AppData\Local\Programs\Python\Python311\Lib\site-packages\google\api_core\gapic_v1\method.py", line 131, in __call__
    return wrapped_func(*args, **kwargs)
           ^^^^^^^^^^^^^^^^^^^^^^^^^^^^^
  File "C:\Users\Nazmul\AppData\Local\Programs\Python\Python311\Lib\site-packages\google\api_core\retry\retry_unary.py", line 294, in retry_wrapped_func
    return retry_target(
           ^^^^^^^^^^^^^
  File "C:\Users\Nazmul\AppData\Local\Programs\Python\Python311\Lib\site-packages\google\api_core\retry\retry_unary.py", line 156, in retry_target
    next_sleep = _retry_error_helper(
                 ^^^^^^^^^^^^^^^^^^^^
  File "C:\Users\Nazmul\AppData\Local\Programs\Python\Python311\Lib\site-packages\google\api_core\retry\retry_base.py", line 214, in _retry_error_helper
    raise final_exc from source_exc
  File "C:\Users\Nazmul\AppData\Local\Programs\Python\Python311\Lib\site-packages\google\api_core\retry\retry_unary.py", line 147, in retry_target
    result = target()
             ^^^^^^^^
  File "C:\Users\Nazmul\AppData\Local\Programs\Python\Python311\Lib\site-packages\google\api_core\timeout.py", line 130, in func_with_timeout
    return func(*args, **kwargs)
           ^^^^^^^^^^^^^^^^^^^^^
  File "C:\Users\Nazmul\AppData\Local\Programs\Python\Python311\Lib\site-packages\google\api_core\grpc_helpers.py", line 78, in error_remapped_callable
    raise exceptions.from_grpc_error(exc) from exc
google.api_core.exceptions.NotFound: 404 models/gemini-pro is not found for API version v1beta, or is not supported for generateContent. Call ListModels to see the list of available models and their supported methods.
Internal Server Error: /api/chat/
C:\Users\Nazmul\Desktop\chatbot\api\views.py changed, reloading.
Watching for file changes with StatReloader
C:\Users\Nazmul\Desktop\chatbot\project\settings.py changed, reloading.
Watching for file changes with StatReloader
Watching for file changes with StatReloader
C:\Users\Nazmul\Desktop\chatbot\project\settings.py changed, reloading.
Watching for file changes with StatReloader
Gemini API Call Error: 404 models/gemini-pro is not found for API version v1beta, or is not supported for generateContent. Call ListModels to see the list of available models and their supported methods.
Traceback (most recent call last):
  File "C:\Users\Nazmul\Desktop\chatbot\api\views.py", line 94, in post
    response = GEMINI_MODEL.generate_content(user_query)
               ^^^^^^^^^^^^^^^^^^^^^^^^^^^^^^^^^^^^^^^^^
  File "C:\Users\Nazmul\AppData\Local\Programs\Python\Python311\Lib\site-packages\google\generativeai\generative_models.py", line 331, in generate_content
    response = self._client.generate_content(
               ^^^^^^^^^^^^^^^^^^^^^^^^^^^^^^
  File "C:\Users\Nazmul\AppData\Local\Programs\Python\Python311\Lib\site-packages\google\ai\generativelanguage_v1beta\services\generative_service\client.py", line 835, in generate_content
    response = rpc(
               ^^^^
  File "C:\Users\Nazmul\AppData\Local\Programs\Python\Python311\Lib\site-packages\google\api_core\gapic_v1\method.py", line 131, in __call__
    return wrapped_func(*args, **kwargs)
           ^^^^^^^^^^^^^^^^^^^^^^^^^^^^^
  File "C:\Users\Nazmul\AppData\Local\Programs\Python\Python311\Lib\site-packages\google\api_core\retry\retry_unary.py", line 294, in retry_wrapped_func
    return retry_target(
           ^^^^^^^^^^^^^
  File "C:\Users\Nazmul\AppData\Local\Programs\Python\Python311\Lib\site-packages\google\api_core\retry\retry_unary.py", line 156, in retry_target
    next_sleep = _retry_error_helper(
                 ^^^^^^^^^^^^^^^^^^^^
  File "C:\Users\Nazmul\AppData\Local\Programs\Python\Python311\Lib\site-packages\google\api_core\retry\retry_base.py", line 214, in _retry_error_helper
    raise final_exc from source_exc
  File "C:\Users\Nazmul\AppData\Local\Programs\Python\Python311\Lib\site-packages\google\api_core\retry\retry_unary.py", line 147, in retry_target
    result = target()
             ^^^^^^^^
  File "C:\Users\Nazmul\AppData\Local\Programs\Python\Python311\Lib\site-packages\google\api_core\timeout.py", line 130, in func_with_timeout
    return func(*args, **kwargs)
           ^^^^^^^^^^^^^^^^^^^^^
  File "C:\Users\Nazmul\AppData\Local\Programs\Python\Python311\Lib\site-packages\google\api_core\grpc_helpers.py", line 78, in error_remapped_callable
    raise exceptions.from_grpc_error(exc) from exc
google.api_core.exceptions.NotFound: 404 models/gemini-pro is not found for API version v1beta, or is not supported for generateContent. Call ListModels to see the list of available models and their supported methods.
Internal Server Error: /api/chat/
Watching for file changes with StatReloader
Gemini API Call Error: 404 models/gemini-pro is not found for API version v1beta, or is not supported for generateContent. Call ListModels to see the list of available models and their supported methods.
Traceback (most recent call last):
  File "C:\Users\Nazmul\Desktop\chatbot\api\views.py", line 94, in post
    response = GEMINI_MODEL.generate_content(user_query)
               ^^^^^^^^^^^^^^^^^^^^^^^^^^^^^^^^^^^^^^^^^
  File "C:\Users\Nazmul\AppData\Local\Programs\Python\Python311\Lib\site-packages\google\generativeai\generative_models.py", line 331, in generate_content
    response = self._client.generate_content(
               ^^^^^^^^^^^^^^^^^^^^^^^^^^^^^^
  File "C:\Users\Nazmul\AppData\Local\Programs\Python\Python311\Lib\site-packages\google\ai\generativelanguage_v1beta\services\generative_service\client.py", line 835, in generate_content
    response = rpc(
               ^^^^
  File "C:\Users\Nazmul\AppData\Local\Programs\Python\Python311\Lib\site-packages\google\api_core\gapic_v1\method.py", line 131, in __call__
    return wrapped_func(*args, **kwargs)
           ^^^^^^^^^^^^^^^^^^^^^^^^^^^^^
  File "C:\Users\Nazmul\AppData\Local\Programs\Python\Python311\Lib\site-packages\google\api_core\retry\retry_unary.py", line 294, in retry_wrapped_func
    return retry_target(
           ^^^^^^^^^^^^^
  File "C:\Users\Nazmul\AppData\Local\Programs\Python\Python311\Lib\site-packages\google\api_core\retry\retry_unary.py", line 156, in retry_target
    next_sleep = _retry_error_helper(
                 ^^^^^^^^^^^^^^^^^^^^
  File "C:\Users\Nazmul\AppData\Local\Programs\Python\Python311\Lib\site-packages\google\api_core\retry\retry_base.py", line 214, in _retry_error_helper
    raise final_exc from source_exc
  File "C:\Users\Nazmul\AppData\Local\Programs\Python\Python311\Lib\site-packages\google\api_core\retry\retry_unary.py", line 147, in retry_target
    result = target()
             ^^^^^^^^
  File "C:\Users\Nazmul\AppData\Local\Programs\Python\Python311\Lib\site-packages\google\api_core\timeout.py", line 130, in func_with_timeout
    return func(*args, **kwargs)
           ^^^^^^^^^^^^^^^^^^^^^
  File "C:\Users\Nazmul\AppData\Local\Programs\Python\Python311\Lib\site-packages\google\api_core\grpc_helpers.py", line 78, in error_remapped_callable
    raise exceptions.from_grpc_error(exc) from exc
google.api_core.exceptions.NotFound: 404 models/gemini-pro is not found for API version v1beta, or is not supported for generateContent. Call ListModels to see the list of available models and their supported methods.
Internal Server Error: /api/chat/
Watching for file changes with StatReloader
Chat interaction saved for user: nazmul
Chat interaction saved for user: nazmul
Chat interaction saved for user: nazmul
Chat interaction saved for user: nazmul
Chat interaction saved for user: nazmul
Chat interaction saved for user: nazmul
Chat interaction saved for user: nazmul
Chat interaction saved for user: nazmul
Chat interaction saved for user: nazmul
