Watching for file changes with StatReloader
Starting new HTTPS connection (1): api.deepseek.com:443
https://api.deepseek.com:443 "POST /v1/chat/completions HTTP/1.1" 400 114
DeepSeek API HTTP error: 400 Client Error: Bad Request for url: https://api.deepseek.com/v1/chat/completions, Status: 400, Response: {"error":{"message":"Model Not Exist","type":"invalid_request_error","param":null,"code":"invalid_request_error"}}
Internal Server Error: /api/chat/
C:\Users\Nazmul\Desktop\chatbot\api\views.py changed, reloading.
Watching for file changes with StatReloader
Watching for file changes with StatReloader
Unauthorized: /api/chat/history/
Unauthorized: /api/token/refresh/
Starting new HTTPS connection (1): api.deepseek.com:443
https://api.deepseek.com:443 "POST /v1/chat/completions HTTP/1.1" 400 114
DeepSeek API HTTP error: 400 Client Error: Bad Request for url: https://api.deepseek.com/v1/chat/completions, Status: 400, Response: {"error":{"message":"Model Not Exist","type":"invalid_request_error","param":null,"code":"invalid_request_error"}}
Internal Server Error: /api/chat/
Starting new HTTPS connection (1): api.deepseek.com:443
https://api.deepseek.com:443 "POST /v1/chat/completions HTTP/1.1" 400 114
DeepSeek API HTTP error: 400 Client Error: Bad Request for url: https://api.deepseek.com/v1/chat/completions, Status: 400, Response: {"error":{"message":"Model Not Exist","type":"invalid_request_error","param":null,"code":"invalid_request_error"}}
Internal Server Error: /api/chat/
C:\Users\Nazmul\Desktop\chatbot\api\views.py changed, reloading.
Watching for file changes with StatReloader
C:\Users\Nazmul\Desktop\chatbot\project\settings.py changed, reloading.
Watching for file changes with StatReloader
C:\Users\Nazmul\Desktop\chatbot\project\settings.py changed, reloading.
Watching for file changes with StatReloader
Unauthorized: /api/chat/history/
Unauthorized: /api/token/refresh/
Starting new HTTPS connection (1): api.deepseek.com:443
https://api.deepseek.com:443 "POST /v1/chat/completions HTTP/1.1" 402 111
DeepSeek API HTTP error: 402 Client Error: Payment Required for url: https://api.deepseek.com/v1/chat/completions, Status: 402, Response: {"error":{"message":"Insufficient Balance","type":"unknown_error","param":null,"code":"invalid_request_error"}}
Internal Server Error: /api/chat/
Starting new HTTPS connection (1): api.deepseek.com:443
https://api.deepseek.com:443 "POST /v1/chat/completions HTTP/1.1" 402 111
DeepSeek API HTTP error: 402 Client Error: Payment Required for url: https://api.deepseek.com/v1/chat/completions, Status: 402, Response: {"error":{"message":"Insufficient Balance","type":"unknown_error","param":null,"code":"invalid_request_error"}}
Internal Server Error: /api/chat/
C:\Users\Nazmul\Desktop\chatbot\api\views.py changed, reloading.
Watching for file changes with StatReloader
Starting new HTTPS connection (1): jsonplaceholder.typicode.com:443
https://jsonplaceholder.typicode.com:443 "POST /posts HTTP/1.1" 201 78
JSONPlaceholder API response saved for user: nazmul
Starting new HTTPS connection (1): jsonplaceholder.typicode.com:443
https://jsonplaceholder.typicode.com:443 "POST /posts HTTP/1.1" 201 94
JSONPlaceholder API response saved for user: nazmul
Starting new HTTPS connection (1): jsonplaceholder.typicode.com:443
https://jsonplaceholder.typicode.com:443 "POST /posts HTTP/1.1" 201 84
JSONPlaceholder API response saved for user: nazmul
Starting new HTTPS connection (1): jsonplaceholder.typicode.com:443
https://jsonplaceholder.typicode.com:443 "POST /posts HTTP/1.1" 201 81
JSONPlaceholder API response saved for user: nazmul
Starting new HTTPS connection (1): jsonplaceholder.typicode.com:443
https://jsonplaceholder.typicode.com:443 "POST /posts HTTP/1.1" 201 103
JSONPlaceholder API response saved for user: nazmul
Successfully imported extension module "markdown.extensions.toc".
Successfully loaded extension "markdown.extensions.toc.TocExtension".
Method Not Allowed: /api/register/
Successfully imported extension module "markdown.extensions.toc".
Successfully loaded extension "markdown.extensions.toc.TocExtension".
Method Not Allowed: /api/token/
Successfully imported extension module "markdown.extensions.toc".
Successfully loaded extension "markdown.extensions.toc.TocExtension".
Unauthorized: /api/chat/
Unauthorized: /api/chat/history/
Unauthorized: /api/chat/history/
Successfully imported extension module "markdown.extensions.toc".
Successfully loaded extension "markdown.extensions.toc.TocExtension".
Successfully imported extension module "markdown.extensions.toc".
Successfully loaded extension "markdown.extensions.toc.TocExtension".
Method Not Allowed: /api/register/
Successfully imported extension module "markdown.extensions.toc".
Successfully loaded extension "markdown.extensions.toc.TocExtension".
Bad Request: /api/register/
Sending JSONPlaceholder API request with prompt: hfai
Starting new HTTPS connection (1): jsonplaceholder.typicode.com:443
https://jsonplaceholder.typicode.com:443 "POST /posts HTTP/1.1" 201 76
Raw JSONPlaceholder API response: {
  "title": "Chatbot Query",
  "body": "hfai",
  "userId": 1,
  "id": 101
}
JSONPlaceholder API response saved for user: nazmul
Successfully imported extension module "markdown.extensions.toc".
Successfully loaded extension "markdown.extensions.toc.TocExtension".
Method Not Allowed: /api/token/
Watching for file changes with StatReloader
Sending JSONPlaceholder API request with prompt: hai
Starting new HTTPS connection (1): jsonplaceholder.typicode.com:443
https://jsonplaceholder.typicode.com:443 "POST /posts HTTP/1.1" 201 75
Raw JSONPlaceholder API response: {
  "title": "Chatbot Query",
  "body": "hai",
  "userId": 1,
  "id": 101
}
JSONPlaceholder API response saved for user: nazmul
Sending JSONPlaceholder API request with prompt: hello
Starting new HTTPS connection (1): jsonplaceholder.typicode.com:443
https://jsonplaceholder.typicode.com:443 "POST /posts HTTP/1.1" 201 77
Raw JSONPlaceholder API response: {
  "title": "Chatbot Query",
  "body": "hello",
  "userId": 1,
  "id": 101
}
JSONPlaceholder API response saved for user: nazmul
C:\Users\Nazmul\Desktop\chatbot\project\settings.py changed, reloading.
Watching for file changes with StatReloader
C:\Users\Nazmul\Desktop\chatbot\api\views.py changed, reloading.
Watching for file changes with StatReloader
Watching for file changes with StatReloader
Internal Server Error: /api/chat/
Traceback (most recent call last):
  File "C:\Users\Nazmul\Desktop\chatbot\api\views.py", line 68, in post
    response = GEMINI_MODEL.generate_content(user_query)
               ^^^^^^^^^^^^^^^^^^^^^^^^^^^^^^^^^^^^^^^^^
  File "C:\Users\Nazmul\AppData\Local\Programs\Python\Python311\Lib\site-packages\google\generativeai\generative_models.py", line 331, in generate_content
    response = self._client.generate_content(
               ^^^^^^^^^^^^^^^^^^^^^^^^^^^^^^
  File "C:\Users\Nazmul\AppData\Local\Programs\Python\Python311\Lib\site-packages\google\ai\generativelanguage_v1beta\services\generative_service\client.py", line 835, in generate_content
    response = rpc(
               ^^^^
  File "C:\Users\Nazmul\AppData\Local\Programs\Python\Python311\Lib\site-packages\google\api_core\gapic_v1\method.py", line 131, in __call__
    return wrapped_func(*args, **kwargs)
           ^^^^^^^^^^^^^^^^^^^^^^^^^^^^^
  File "C:\Users\Nazmul\AppData\Local\Programs\Python\Python311\Lib\site-packages\google\api_core\retry\retry_unary.py", line 294, in retry_wrapped_func
    return retry_target(
           ^^^^^^^^^^^^^
  File "C:\Users\Nazmul\AppData\Local\Programs\Python\Python311\Lib\site-packages\google\api_core\retry\retry_unary.py", line 156, in retry_target
    next_sleep = _retry_error_helper(
                 ^^^^^^^^^^^^^^^^^^^^
  File "C:\Users\Nazmul\AppData\Local\Programs\Python\Python311\Lib\site-packages\google\api_core\retry\retry_base.py", line 214, in _retry_error_helper
    raise final_exc from source_exc
  File "C:\Users\Nazmul\AppData\Local\Programs\Python\Python311\Lib\site-packages\google\api_core\retry\retry_unary.py", line 147, in retry_target
    result = target()
             ^^^^^^^^
  File "C:\Users\Nazmul\AppData\Local\Programs\Python\Python311\Lib\site-packages\google\api_core\timeout.py", line 130, in func_with_timeout
    return func(*args, **kwargs)
           ^^^^^^^^^^^^^^^^^^^^^
  File "C:\Users\Nazmul\AppData\Local\Programs\Python\Python311\Lib\site-packages\google\api_core\grpc_helpers.py", line 78, in error_remapped_callable
    raise exceptions.from_grpc_error(exc) from exc
google.api_core.exceptions.NotFound: 404 models/gemini-pro is not found for API version v1beta, or is not supported for generateContent. Call ListModels to see the list of available models and their supported methods.

During handling of the above exception, another exception occurred:

Traceback (most recent call last):
  File "C:\Users\Nazmul\AppData\Local\Programs\Python\Python311\Lib\site-packages\django\core\handlers\exception.py", line 55, in inner
    response = get_response(request)
               ^^^^^^^^^^^^^^^^^^^^^
  File "C:\Users\Nazmul\AppData\Local\Programs\Python\Python311\Lib\site-packages\django\core\handlers\base.py", line 197, in _get_response
    response = wrapped_callback(request, *callback_args, **callback_kwargs)
               ^^^^^^^^^^^^^^^^^^^^^^^^^^^^^^^^^^^^^^^^^^^^^^^^^^^^^^^^^^^^
  File "C:\Users\Nazmul\AppData\Local\Programs\Python\Python311\Lib\site-packages\django\views\decorators\csrf.py", line 65, in _view_wrapper
    return view_func(request, *args, **kwargs)
           ^^^^^^^^^^^^^^^^^^^^^^^^^^^^^^^^^^^
  File "C:\Users\Nazmul\AppData\Local\Programs\Python\Python311\Lib\site-packages\django\views\generic\base.py", line 105, in view
    return self.dispatch(request, *args, **kwargs)
           ^^^^^^^^^^^^^^^^^^^^^^^^^^^^^^^^^^^^^^^
  File "C:\Users\Nazmul\AppData\Local\Programs\Python\Python311\Lib\site-packages\rest_framework\views.py", line 515, in dispatch
    response = self.handle_exception(exc)
               ^^^^^^^^^^^^^^^^^^^^^^^^^^
  File "C:\Users\Nazmul\AppData\Local\Programs\Python\Python311\Lib\site-packages\rest_framework\views.py", line 475, in handle_exception
    self.raise_uncaught_exception(exc)
  File "C:\Users\Nazmul\AppData\Local\Programs\Python\Python311\Lib\site-packages\rest_framework\views.py", line 486, in raise_uncaught_exception
    raise exc
  File "C:\Users\Nazmul\AppData\Local\Programs\Python\Python311\Lib\site-packages\rest_framework\views.py", line 512, in dispatch
    response = handler(request, *args, **kwargs)
               ^^^^^^^^^^^^^^^^^^^^^^^^^^^^^^^^^
  File "C:\Users\Nazmul\Desktop\chatbot\api\views.py", line 94, in post
    except genai.types.APIError as e:
           ^^^^^^^^^^^^^^^^^^^^
AttributeError: module 'google.generativeai.types' has no attribute 'APIError'
C:\Users\Nazmul\Desktop\chatbot\api\urls.py changed, reloading.
Watching for file changes with StatReloader
Internal Server Error: /api/chat/
Traceback (most recent call last):
  File "C:\Users\Nazmul\Desktop\chatbot\api\views.py", line 68, in post
    response = GEMINI_MODEL.generate_content(user_query)
               ^^^^^^^^^^^^^^^^^^^^^^^^^^^^^^^^^^^^^^^^^
  File "C:\Users\Nazmul\AppData\Local\Programs\Python\Python311\Lib\site-packages\google\generativeai\generative_models.py", line 331, in generate_content
    response = self._client.generate_content(
               ^^^^^^^^^^^^^^^^^^^^^^^^^^^^^^
  File "C:\Users\Nazmul\AppData\Local\Programs\Python\Python311\Lib\site-packages\google\ai\generativelanguage_v1beta\services\generative_service\client.py", line 835, in generate_content
    response = rpc(
               ^^^^
  File "C:\Users\Nazmul\AppData\Local\Programs\Python\Python311\Lib\site-packages\google\api_core\gapic_v1\method.py", line 131, in __call__
    return wrapped_func(*args, **kwargs)
           ^^^^^^^^^^^^^^^^^^^^^^^^^^^^^
  File "C:\Users\Nazmul\AppData\Local\Programs\Python\Python311\Lib\site-packages\google\api_core\retry\retry_unary.py", line 294, in retry_wrapped_func
    return retry_target(
           ^^^^^^^^^^^^^
  File "C:\Users\Nazmul\AppData\Local\Programs\Python\Python311\Lib\site-packages\google\api_core\retry\retry_unary.py", line 156, in retry_target
    next_sleep = _retry_error_helper(
                 ^^^^^^^^^^^^^^^^^^^^
  File "C:\Users\Nazmul\AppData\Local\Programs\Python\Python311\Lib\site-packages\google\api_core\retry\retry_base.py", line 214, in _retry_error_helper
    raise final_exc from source_exc
  File "C:\Users\Nazmul\AppData\Local\Programs\Python\Python311\Lib\site-packages\google\api_core\retry\retry_unary.py", line 147, in retry_target
    result = target()
             ^^^^^^^^
  File "C:\Users\Nazmul\AppData\Local\Programs\Python\Python311\Lib\site-packages\google\api_core\timeout.py", line 130, in func_with_timeout
    return func(*args, **kwargs)
           ^^^^^^^^^^^^^^^^^^^^^
  File "C:\Users\Nazmul\AppData\Local\Programs\Python\Python311\Lib\site-packages\google\api_core\grpc_helpers.py", line 78, in error_remapped_callable
    raise exceptions.from_grpc_error(exc) from exc
google.api_core.exceptions.NotFound: 404 models/gemini-pro is not found for API version v1beta, or is not supported for generateContent. Call ListModels to see the list of available models and their supported methods.

During handling of the above exception, another exception occurred:

Traceback (most recent call last):
  File "C:\Users\Nazmul\AppData\Local\Programs\Python\Python311\Lib\site-packages\django\core\handlers\exception.py", line 55, in inner
    response = get_response(request)
               ^^^^^^^^^^^^^^^^^^^^^
  File "C:\Users\Nazmul\AppData\Local\Programs\Python\Python311\Lib\site-packages\django\core\handlers\base.py", line 197, in _get_response
    response = wrapped_callback(request, *callback_args, **callback_kwargs)
               ^^^^^^^^^^^^^^^^^^^^^^^^^^^^^^^^^^^^^^^^^^^^^^^^^^^^^^^^^^^^
  File "C:\Users\Nazmul\AppData\Local\Programs\Python\Python311\Lib\site-packages\django\views\decorators\csrf.py", line 65, in _view_wrapper
    return view_func(request, *args, **kwargs)
           ^^^^^^^^^^^^^^^^^^^^^^^^^^^^^^^^^^^
  File "C:\Users\Nazmul\AppData\Local\Programs\Python\Python311\Lib\site-packages\django\views\generic\base.py", line 105, in view
    return self.dispatch(request, *args, **kwargs)
           ^^^^^^^^^^^^^^^^^^^^^^^^^^^^^^^^^^^^^^^
  File "C:\Users\Nazmul\AppData\Local\Programs\Python\Python311\Lib\site-packages\rest_framework\views.py", line 515, in dispatch
    response = self.handle_exception(exc)
               ^^^^^^^^^^^^^^^^^^^^^^^^^^
  File "C:\Users\Nazmul\AppData\Local\Programs\Python\Python311\Lib\site-packages\rest_framework\views.py", line 475, in handle_exception
    self.raise_uncaught_exception(exc)
  File "C:\Users\Nazmul\AppData\Local\Programs\Python\Python311\Lib\site-packages\rest_framework\views.py", line 486, in raise_uncaught_exception
    raise exc
  File "C:\Users\Nazmul\AppData\Local\Programs\Python\Python311\Lib\site-packages\rest_framework\views.py", line 512, in dispatch
    response = handler(request, *args, **kwargs)
               ^^^^^^^^^^^^^^^^^^^^^^^^^^^^^^^^^
  File "C:\Users\Nazmul\Desktop\chatbot\api\views.py", line 94, in post
    except genai.types.APIError as e:
           ^^^^^^^^^^^^^^^^^^^^
AttributeError: module 'google.generativeai.types' has no attribute 'APIError'
C:\Users\Nazmul\Desktop\chatbot\api\views.py changed, reloading.
Watching for file changes with StatReloader
Internal Server Error: /api/chat/
Traceback (most recent call last):
  File "C:\Users\Nazmul\Desktop\chatbot\api\views.py", line 66, in post
    response = GEMINI_MODEL.generate_content(user_query)
               ^^^^^^^^^^^^^^^^^^^^^^^^^^^^^^^^^^^^^^^^^
  File "C:\Users\Nazmul\AppData\Local\Programs\Python\Python311\Lib\site-packages\google\generativeai\generative_models.py", line 331, in generate_content
    response = self._client.generate_content(
               ^^^^^^^^^^^^^^^^^^^^^^^^^^^^^^
  File "C:\Users\Nazmul\AppData\Local\Programs\Python\Python311\Lib\site-packages\google\ai\generativelanguage_v1beta\services\generative_service\client.py", line 835, in generate_content
    response = rpc(
               ^^^^
  File "C:\Users\Nazmul\AppData\Local\Programs\Python\Python311\Lib\site-packages\google\api_core\gapic_v1\method.py", line 131, in __call__
    return wrapped_func(*args, **kwargs)
           ^^^^^^^^^^^^^^^^^^^^^^^^^^^^^
  File "C:\Users\Nazmul\AppData\Local\Programs\Python\Python311\Lib\site-packages\google\api_core\retry\retry_unary.py", line 294, in retry_wrapped_func
    return retry_target(
           ^^^^^^^^^^^^^
  File "C:\Users\Nazmul\AppData\Local\Programs\Python\Python311\Lib\site-packages\google\api_core\retry\retry_unary.py", line 156, in retry_target
    next_sleep = _retry_error_helper(
                 ^^^^^^^^^^^^^^^^^^^^
  File "C:\Users\Nazmul\AppData\Local\Programs\Python\Python311\Lib\site-packages\google\api_core\retry\retry_base.py", line 214, in _retry_error_helper
    raise final_exc from source_exc
  File "C:\Users\Nazmul\AppData\Local\Programs\Python\Python311\Lib\site-packages\google\api_core\retry\retry_unary.py", line 147, in retry_target
    result = target()
             ^^^^^^^^
  File "C:\Users\Nazmul\AppData\Local\Programs\Python\Python311\Lib\site-packages\google\api_core\timeout.py", line 130, in func_with_timeout
    return func(*args, **kwargs)
           ^^^^^^^^^^^^^^^^^^^^^
  File "C:\Users\Nazmul\AppData\Local\Programs\Python\Python311\Lib\site-packages\google\api_core\grpc_helpers.py", line 78, in error_remapped_callable
    raise exceptions.from_grpc_error(exc) from exc
google.api_core.exceptions.NotFound: 404 models/gemini-pro is not found for API version v1beta, or is not supported for generateContent. Call ListModels to see the list of available models and their supported methods.

During handling of the above exception, another exception occurred:

Traceback (most recent call last):
  File "C:\Users\Nazmul\AppData\Local\Programs\Python\Python311\Lib\site-packages\django\core\handlers\exception.py", line 55, in inner
    response = get_response(request)
               ^^^^^^^^^^^^^^^^^^^^^
  File "C:\Users\Nazmul\AppData\Local\Programs\Python\Python311\Lib\site-packages\django\core\handlers\base.py", line 197, in _get_response
    response = wrapped_callback(request, *callback_args, **callback_kwargs)
               ^^^^^^^^^^^^^^^^^^^^^^^^^^^^^^^^^^^^^^^^^^^^^^^^^^^^^^^^^^^^
  File "C:\Users\Nazmul\AppData\Local\Programs\Python\Python311\Lib\site-packages\django\views\decorators\csrf.py", line 65, in _view_wrapper
    return view_func(request, *args, **kwargs)
           ^^^^^^^^^^^^^^^^^^^^^^^^^^^^^^^^^^^
  File "C:\Users\Nazmul\AppData\Local\Programs\Python\Python311\Lib\site-packages\django\views\generic\base.py", line 105, in view
    return self.dispatch(request, *args, **kwargs)
           ^^^^^^^^^^^^^^^^^^^^^^^^^^^^^^^^^^^^^^^
  File "C:\Users\Nazmul\AppData\Local\Programs\Python\Python311\Lib\site-packages\rest_framework\views.py", line 515, in dispatch
    response = self.handle_exception(exc)
               ^^^^^^^^^^^^^^^^^^^^^^^^^^
  File "C:\Users\Nazmul\AppData\Local\Programs\Python\Python311\Lib\site-packages\rest_framework\views.py", line 475, in handle_exception
    self.raise_uncaught_exception(exc)
  File "C:\Users\Nazmul\AppData\Local\Programs\Python\Python311\Lib\site-packages\rest_framework\views.py", line 486, in raise_uncaught_exception
    raise exc
  File "C:\Users\Nazmul\AppData\Local\Programs\Python\Python311\Lib\site-packages\rest_framework\views.py", line 512, in dispatch
    response = handler(request, *args, **kwargs)
               ^^^^^^^^^^^^^^^^^^^^^^^^^^^^^^^^^
  File "C:\Users\Nazmul\Desktop\chatbot\api\views.py", line 92, in post
    except genai.types.APIError as e:
           ^^^^^^^^^^^^^^^^^^^^
AttributeError: module 'google.generativeai.types' has no attribute 'APIError'
Internal Server Error: /api/chat/
Traceback (most recent call last):
  File "C:\Users\Nazmul\Desktop\chatbot\api\views.py", line 66, in post
    response = GEMINI_MODEL.generate_content(user_query)
               ^^^^^^^^^^^^^^^^^^^^^^^^^^^^^^^^^^^^^^^^^
  File "C:\Users\Nazmul\AppData\Local\Programs\Python\Python311\Lib\site-packages\google\generativeai\generative_models.py", line 331, in generate_content
    response = self._client.generate_content(
               ^^^^^^^^^^^^^^^^^^^^^^^^^^^^^^
  File "C:\Users\Nazmul\AppData\Local\Programs\Python\Python311\Lib\site-packages\google\ai\generativelanguage_v1beta\services\generative_service\client.py", line 835, in generate_content
    response = rpc(
               ^^^^
  File "C:\Users\Nazmul\AppData\Local\Programs\Python\Python311\Lib\site-packages\google\api_core\gapic_v1\method.py", line 131, in __call__
    return wrapped_func(*args, **kwargs)
           ^^^^^^^^^^^^^^^^^^^^^^^^^^^^^
  File "C:\Users\Nazmul\AppData\Local\Programs\Python\Python311\Lib\site-packages\google\api_core\retry\retry_unary.py", line 294, in retry_wrapped_func
    return retry_target(
           ^^^^^^^^^^^^^
  File "C:\Users\Nazmul\AppData\Local\Programs\Python\Python311\Lib\site-packages\google\api_core\retry\retry_unary.py", line 156, in retry_target
    next_sleep = _retry_error_helper(
                 ^^^^^^^^^^^^^^^^^^^^
  File "C:\Users\Nazmul\AppData\Local\Programs\Python\Python311\Lib\site-packages\google\api_core\retry\retry_base.py", line 214, in _retry_error_helper
    raise final_exc from source_exc
  File "C:\Users\Nazmul\AppData\Local\Programs\Python\Python311\Lib\site-packages\google\api_core\retry\retry_unary.py", line 147, in retry_target
    result = target()
             ^^^^^^^^
  File "C:\Users\Nazmul\AppData\Local\Programs\Python\Python311\Lib\site-packages\google\api_core\timeout.py", line 130, in func_with_timeout
    return func(*args, **kwargs)
           ^^^^^^^^^^^^^^^^^^^^^
  File "C:\Users\Nazmul\AppData\Local\Programs\Python\Python311\Lib\site-packages\google\api_core\grpc_helpers.py", line 78, in error_remapped_callable
    raise exceptions.from_grpc_error(exc) from exc
google.api_core.exceptions.NotFound: 404 models/gemini-pro is not found for API version v1beta, or is not supported for generateContent. Call ListModels to see the list of available models and their supported methods.

During handling of the above exception, another exception occurred:

Traceback (most recent call last):
  File "C:\Users\Nazmul\AppData\Local\Programs\Python\Python311\Lib\site-packages\django\core\handlers\exception.py", line 55, in inner
    response = get_response(request)
               ^^^^^^^^^^^^^^^^^^^^^
  File "C:\Users\Nazmul\AppData\Local\Programs\Python\Python311\Lib\site-packages\django\core\handlers\base.py", line 197, in _get_response
    response = wrapped_callback(request, *callback_args, **callback_kwargs)
               ^^^^^^^^^^^^^^^^^^^^^^^^^^^^^^^^^^^^^^^^^^^^^^^^^^^^^^^^^^^^
  File "C:\Users\Nazmul\AppData\Local\Programs\Python\Python311\Lib\site-packages\django\views\decorators\csrf.py", line 65, in _view_wrapper
    return view_func(request, *args, **kwargs)
           ^^^^^^^^^^^^^^^^^^^^^^^^^^^^^^^^^^^
  File "C:\Users\Nazmul\AppData\Local\Programs\Python\Python311\Lib\site-packages\django\views\generic\base.py", line 105, in view
    return self.dispatch(request, *args, **kwargs)
           ^^^^^^^^^^^^^^^^^^^^^^^^^^^^^^^^^^^^^^^
  File "C:\Users\Nazmul\AppData\Local\Programs\Python\Python311\Lib\site-packages\rest_framework\views.py", line 515, in dispatch
    response = self.handle_exception(exc)
               ^^^^^^^^^^^^^^^^^^^^^^^^^^
  File "C:\Users\Nazmul\AppData\Local\Programs\Python\Python311\Lib\site-packages\rest_framework\views.py", line 475, in handle_exception
    self.raise_uncaught_exception(exc)
  File "C:\Users\Nazmul\AppData\Local\Programs\Python\Python311\Lib\site-packages\rest_framework\views.py", line 486, in raise_uncaught_exception
    raise exc
  File "C:\Users\Nazmul\AppData\Local\Programs\Python\Python311\Lib\site-packages\rest_framework\views.py", line 512, in dispatch
    response = handler(request, *args, **kwargs)
               ^^^^^^^^^^^^^^^^^^^^^^^^^^^^^^^^^
  File "C:\Users\Nazmul\Desktop\chatbot\api\views.py", line 92, in post
    except genai.types.APIError as e:
           ^^^^^^^^^^^^^^^^^^^^
AttributeError: module 'google.generativeai.types' has no attribute 'APIError'
Watching for file changes with StatReloader
Sending query to Gemini API: ha
Internal Server Error: /api/chat/
Traceback (most recent call last):
  File "C:\Users\Nazmul\Desktop\chatbot\api\views.py", line 66, in post
    response = GEMINI_MODEL.generate_content(user_query)
               ^^^^^^^^^^^^^^^^^^^^^^^^^^^^^^^^^^^^^^^^^
  File "C:\Users\Nazmul\AppData\Local\Programs\Python\Python311\Lib\site-packages\google\generativeai\generative_models.py", line 331, in generate_content
    response = self._client.generate_content(
               ^^^^^^^^^^^^^^^^^^^^^^^^^^^^^^
  File "C:\Users\Nazmul\AppData\Local\Programs\Python\Python311\Lib\site-packages\google\ai\generativelanguage_v1beta\services\generative_service\client.py", line 835, in generate_content
    response = rpc(
               ^^^^
  File "C:\Users\Nazmul\AppData\Local\Programs\Python\Python311\Lib\site-packages\google\api_core\gapic_v1\method.py", line 131, in __call__
    return wrapped_func(*args, **kwargs)
           ^^^^^^^^^^^^^^^^^^^^^^^^^^^^^
  File "C:\Users\Nazmul\AppData\Local\Programs\Python\Python311\Lib\site-packages\google\api_core\retry\retry_unary.py", line 294, in retry_wrapped_func
    return retry_target(
           ^^^^^^^^^^^^^
  File "C:\Users\Nazmul\AppData\Local\Programs\Python\Python311\Lib\site-packages\google\api_core\retry\retry_unary.py", line 156, in retry_target
    next_sleep = _retry_error_helper(
                 ^^^^^^^^^^^^^^^^^^^^
  File "C:\Users\Nazmul\AppData\Local\Programs\Python\Python311\Lib\site-packages\google\api_core\retry\retry_base.py", line 214, in _retry_error_helper
    raise final_exc from source_exc
  File "C:\Users\Nazmul\AppData\Local\Programs\Python\Python311\Lib\site-packages\google\api_core\retry\retry_unary.py", line 147, in retry_target
    result = target()
             ^^^^^^^^
  File "C:\Users\Nazmul\AppData\Local\Programs\Python\Python311\Lib\site-packages\google\api_core\timeout.py", line 130, in func_with_timeout
    return func(*args, **kwargs)
           ^^^^^^^^^^^^^^^^^^^^^
  File "C:\Users\Nazmul\AppData\Local\Programs\Python\Python311\Lib\site-packages\google\api_core\grpc_helpers.py", line 78, in error_remapped_callable
    raise exceptions.from_grpc_error(exc) from exc
google.api_core.exceptions.NotFound: 404 models/gemini-pro is not found for API version v1beta, or is not supported for generateContent. Call ListModels to see the list of available models and their supported methods.

During handling of the above exception, another exception occurred:

Traceback (most recent call last):
  File "C:\Users\Nazmul\AppData\Local\Programs\Python\Python311\Lib\site-packages\django\core\handlers\exception.py", line 55, in inner
    response = get_response(request)
               ^^^^^^^^^^^^^^^^^^^^^
  File "C:\Users\Nazmul\AppData\Local\Programs\Python\Python311\Lib\site-packages\django\core\handlers\base.py", line 197, in _get_response
    response = wrapped_callback(request, *callback_args, **callback_kwargs)
               ^^^^^^^^^^^^^^^^^^^^^^^^^^^^^^^^^^^^^^^^^^^^^^^^^^^^^^^^^^^^
  File "C:\Users\Nazmul\AppData\Local\Programs\Python\Python311\Lib\site-packages\django\views\decorators\csrf.py", line 65, in _view_wrapper
    return view_func(request, *args, **kwargs)
           ^^^^^^^^^^^^^^^^^^^^^^^^^^^^^^^^^^^
  File "C:\Users\Nazmul\AppData\Local\Programs\Python\Python311\Lib\site-packages\django\views\generic\base.py", line 105, in view
    return self.dispatch(request, *args, **kwargs)
           ^^^^^^^^^^^^^^^^^^^^^^^^^^^^^^^^^^^^^^^
  File "C:\Users\Nazmul\AppData\Local\Programs\Python\Python311\Lib\site-packages\rest_framework\views.py", line 515, in dispatch
    response = self.handle_exception(exc)
               ^^^^^^^^^^^^^^^^^^^^^^^^^^
  File "C:\Users\Nazmul\AppData\Local\Programs\Python\Python311\Lib\site-packages\rest_framework\views.py", line 475, in handle_exception
    self.raise_uncaught_exception(exc)
  File "C:\Users\Nazmul\AppData\Local\Programs\Python\Python311\Lib\site-packages\rest_framework\views.py", line 486, in raise_uncaught_exception
    raise exc
  File "C:\Users\Nazmul\AppData\Local\Programs\Python\Python311\Lib\site-packages\rest_framework\views.py", line 512, in dispatch
    response = handler(request, *args, **kwargs)
               ^^^^^^^^^^^^^^^^^^^^^^^^^^^^^^^^^
  File "C:\Users\Nazmul\Desktop\chatbot\api\views.py", line 92, in post
    except genai.types.APIError as e:
           ^^^^^^^^^^^^^^^^^^^^
AttributeError: module 'google.generativeai.types' has no attribute 'APIError'
Unauthorized: /api/chat/
Successfully imported extension module "markdown.extensions.toc".
Successfully loaded extension "markdown.extensions.toc.TocExtension".
Method Not Allowed: /api/token/
Successfully imported extension module "markdown.extensions.toc".
Successfully loaded extension "markdown.extensions.toc.TocExtension".
Unauthorized: /api/chat/
Sending query to Gemini API: rer
Internal Server Error: /api/chat/
Traceback (most recent call last):
  File "C:\Users\Nazmul\Desktop\chatbot\api\views.py", line 66, in post
    response = GEMINI_MODEL.generate_content(user_query)
               ^^^^^^^^^^^^^^^^^^^^^^^^^^^^^^^^^^^^^^^^^
  File "C:\Users\Nazmul\AppData\Local\Programs\Python\Python311\Lib\site-packages\google\generativeai\generative_models.py", line 331, in generate_content
    response = self._client.generate_content(
               ^^^^^^^^^^^^^^^^^^^^^^^^^^^^^^
  File "C:\Users\Nazmul\AppData\Local\Programs\Python\Python311\Lib\site-packages\google\ai\generativelanguage_v1beta\services\generative_service\client.py", line 835, in generate_content
    response = rpc(
               ^^^^
  File "C:\Users\Nazmul\AppData\Local\Programs\Python\Python311\Lib\site-packages\google\api_core\gapic_v1\method.py", line 131, in __call__
    return wrapped_func(*args, **kwargs)
           ^^^^^^^^^^^^^^^^^^^^^^^^^^^^^
  File "C:\Users\Nazmul\AppData\Local\Programs\Python\Python311\Lib\site-packages\google\api_core\retry\retry_unary.py", line 294, in retry_wrapped_func
    return retry_target(
           ^^^^^^^^^^^^^
  File "C:\Users\Nazmul\AppData\Local\Programs\Python\Python311\Lib\site-packages\google\api_core\retry\retry_unary.py", line 156, in retry_target
    next_sleep = _retry_error_helper(
                 ^^^^^^^^^^^^^^^^^^^^
  File "C:\Users\Nazmul\AppData\Local\Programs\Python\Python311\Lib\site-packages\google\api_core\retry\retry_base.py", line 214, in _retry_error_helper
    raise final_exc from source_exc
  File "C:\Users\Nazmul\AppData\Local\Programs\Python\Python311\Lib\site-packages\google\api_core\retry\retry_unary.py", line 147, in retry_target
    result = target()
             ^^^^^^^^
  File "C:\Users\Nazmul\AppData\Local\Programs\Python\Python311\Lib\site-packages\google\api_core\timeout.py", line 130, in func_with_timeout
    return func(*args, **kwargs)
           ^^^^^^^^^^^^^^^^^^^^^
  File "C:\Users\Nazmul\AppData\Local\Programs\Python\Python311\Lib\site-packages\google\api_core\grpc_helpers.py", line 78, in error_remapped_callable
    raise exceptions.from_grpc_error(exc) from exc
google.api_core.exceptions.NotFound: 404 models/gemini-pro is not found for API version v1beta, or is not supported for generateContent. Call ListModels to see the list of available models and their supported methods.

During handling of the above exception, another exception occurred:

Traceback (most recent call last):
  File "C:\Users\Nazmul\AppData\Local\Programs\Python\Python311\Lib\site-packages\django\core\handlers\exception.py", line 55, in inner
    response = get_response(request)
               ^^^^^^^^^^^^^^^^^^^^^
  File "C:\Users\Nazmul\AppData\Local\Programs\Python\Python311\Lib\site-packages\django\core\handlers\base.py", line 197, in _get_response
    response = wrapped_callback(request, *callback_args, **callback_kwargs)
               ^^^^^^^^^^^^^^^^^^^^^^^^^^^^^^^^^^^^^^^^^^^^^^^^^^^^^^^^^^^^
  File "C:\Users\Nazmul\AppData\Local\Programs\Python\Python311\Lib\site-packages\django\views\decorators\csrf.py", line 65, in _view_wrapper
    return view_func(request, *args, **kwargs)
           ^^^^^^^^^^^^^^^^^^^^^^^^^^^^^^^^^^^
  File "C:\Users\Nazmul\AppData\Local\Programs\Python\Python311\Lib\site-packages\django\views\generic\base.py", line 105, in view
    return self.dispatch(request, *args, **kwargs)
           ^^^^^^^^^^^^^^^^^^^^^^^^^^^^^^^^^^^^^^^
  File "C:\Users\Nazmul\AppData\Local\Programs\Python\Python311\Lib\site-packages\rest_framework\views.py", line 515, in dispatch
    response = self.handle_exception(exc)
               ^^^^^^^^^^^^^^^^^^^^^^^^^^
  File "C:\Users\Nazmul\AppData\Local\Programs\Python\Python311\Lib\site-packages\rest_framework\views.py", line 475, in handle_exception
    self.raise_uncaught_exception(exc)
  File "C:\Users\Nazmul\AppData\Local\Programs\Python\Python311\Lib\site-packages\rest_framework\views.py", line 486, in raise_uncaught_exception
    raise exc
  File "C:\Users\Nazmul\AppData\Local\Programs\Python\Python311\Lib\site-packages\rest_framework\views.py", line 512, in dispatch
    response = handler(request, *args, **kwargs)
               ^^^^^^^^^^^^^^^^^^^^^^^^^^^^^^^^^
  File "C:\Users\Nazmul\Desktop\chatbot\api\views.py", line 92, in post
    except genai.types.APIError as e:
           ^^^^^^^^^^^^^^^^^^^^
AttributeError: module 'google.generativeai.types' has no attribute 'APIError'
C:\Users\Nazmul\Desktop\chatbot\project\settings.py changed, reloading.
Watching for file changes with StatReloader
Watching for file changes with StatReloader
Unauthorized: /api/chat/history/
Internal Server Error: /api/token/refresh/
Traceback (most recent call last):
  File "C:\Users\Nazmul\AppData\Local\Programs\Python\Python311\Lib\site-packages\django\core\handlers\exception.py", line 55, in inner
    response = get_response(request)
               ^^^^^^^^^^^^^^^^^^^^^
  File "C:\Users\Nazmul\AppData\Local\Programs\Python\Python311\Lib\site-packages\django\core\handlers\base.py", line 197, in _get_response
    response = wrapped_callback(request, *callback_args, **callback_kwargs)
               ^^^^^^^^^^^^^^^^^^^^^^^^^^^^^^^^^^^^^^^^^^^^^^^^^^^^^^^^^^^^
  File "C:\Users\Nazmul\AppData\Local\Programs\Python\Python311\Lib\site-packages\django\views\decorators\csrf.py", line 65, in _view_wrapper
    return view_func(request, *args, **kwargs)
           ^^^^^^^^^^^^^^^^^^^^^^^^^^^^^^^^^^^
  File "C:\Users\Nazmul\AppData\Local\Programs\Python\Python311\Lib\site-packages\django\views\generic\base.py", line 105, in view
    return self.dispatch(request, *args, **kwargs)
           ^^^^^^^^^^^^^^^^^^^^^^^^^^^^^^^^^^^^^^^
  File "C:\Users\Nazmul\AppData\Local\Programs\Python\Python311\Lib\site-packages\rest_framework\views.py", line 515, in dispatch
    response = self.handle_exception(exc)
               ^^^^^^^^^^^^^^^^^^^^^^^^^^
  File "C:\Users\Nazmul\AppData\Local\Programs\Python\Python311\Lib\site-packages\rest_framework\views.py", line 475, in handle_exception
    self.raise_uncaught_exception(exc)
  File "C:\Users\Nazmul\AppData\Local\Programs\Python\Python311\Lib\site-packages\rest_framework\views.py", line 486, in raise_uncaught_exception
    raise exc
  File "C:\Users\Nazmul\AppData\Local\Programs\Python\Python311\Lib\site-packages\rest_framework\views.py", line 512, in dispatch
    response = handler(request, *args, **kwargs)
               ^^^^^^^^^^^^^^^^^^^^^^^^^^^^^^^^^
  File "C:\Users\Nazmul\AppData\Local\Programs\Python\Python311\Lib\site-packages\rest_framework_simplejwt\views.py", line 44, in post
    serializer.is_valid(raise_exception=True)
  File "C:\Users\Nazmul\AppData\Local\Programs\Python\Python311\Lib\site-packages\rest_framework\serializers.py", line 225, in is_valid
    self._validated_data = self.run_validation(self.initial_data)
                           ^^^^^^^^^^^^^^^^^^^^^^^^^^^^^^^^^^^^^^
  File "C:\Users\Nazmul\AppData\Local\Programs\Python\Python311\Lib\site-packages\rest_framework\serializers.py", line 447, in run_validation
    value = self.validate(value)
            ^^^^^^^^^^^^^^^^^^^^
  File "C:\Users\Nazmul\AppData\Local\Programs\Python\Python311\Lib\site-packages\rest_framework_simplejwt\serializers.py", line 141, in validate
    refresh.outstand()
  File "C:\Users\Nazmul\AppData\Local\Programs\Python\Python311\Lib\site-packages\rest_framework_simplejwt\tokens.py", line 222, in outstand
    return OutstandingToken.objects.get_or_create(
           ^^^^^^^^^^^^^^^^^^^^^^^^
AttributeError: type object 'OutstandingToken' has no attribute 'objects'
Sending query to Gemini API: cdf
Internal Server Error: /api/chat/
Traceback (most recent call last):
  File "C:\Users\Nazmul\Desktop\chatbot\api\views.py", line 66, in post
    response = GEMINI_MODEL.generate_content(user_query)
               ^^^^^^^^^^^^^^^^^^^^^^^^^^^^^^^^^^^^^^^^^
  File "C:\Users\Nazmul\AppData\Local\Programs\Python\Python311\Lib\site-packages\google\generativeai\generative_models.py", line 331, in generate_content
    response = self._client.generate_content(
               ^^^^^^^^^^^^^^^^^^^^^^^^^^^^^^
  File "C:\Users\Nazmul\AppData\Local\Programs\Python\Python311\Lib\site-packages\google\ai\generativelanguage_v1beta\services\generative_service\client.py", line 835, in generate_content
    response = rpc(
               ^^^^
  File "C:\Users\Nazmul\AppData\Local\Programs\Python\Python311\Lib\site-packages\google\api_core\gapic_v1\method.py", line 131, in __call__
    return wrapped_func(*args, **kwargs)
           ^^^^^^^^^^^^^^^^^^^^^^^^^^^^^
  File "C:\Users\Nazmul\AppData\Local\Programs\Python\Python311\Lib\site-packages\google\api_core\retry\retry_unary.py", line 294, in retry_wrapped_func
    return retry_target(
           ^^^^^^^^^^^^^
  File "C:\Users\Nazmul\AppData\Local\Programs\Python\Python311\Lib\site-packages\google\api_core\retry\retry_unary.py", line 156, in retry_target
    next_sleep = _retry_error_helper(
                 ^^^^^^^^^^^^^^^^^^^^
  File "C:\Users\Nazmul\AppData\Local\Programs\Python\Python311\Lib\site-packages\google\api_core\retry\retry_base.py", line 214, in _retry_error_helper
    raise final_exc from source_exc
  File "C:\Users\Nazmul\AppData\Local\Programs\Python\Python311\Lib\site-packages\google\api_core\retry\retry_unary.py", line 147, in retry_target
    result = target()
             ^^^^^^^^
  File "C:\Users\Nazmul\AppData\Local\Programs\Python\Python311\Lib\site-packages\google\api_core\timeout.py", line 130, in func_with_timeout
    return func(*args, **kwargs)
           ^^^^^^^^^^^^^^^^^^^^^
  File "C:\Users\Nazmul\AppData\Local\Programs\Python\Python311\Lib\site-packages\google\api_core\grpc_helpers.py", line 78, in error_remapped_callable
    raise exceptions.from_grpc_error(exc) from exc
google.api_core.exceptions.NotFound: 404 models/gemini-pro is not found for API version v1beta, or is not supported for generateContent. Call ListModels to see the list of available models and their supported methods.

During handling of the above exception, another exception occurred:

Traceback (most recent call last):
  File "C:\Users\Nazmul\AppData\Local\Programs\Python\Python311\Lib\site-packages\django\core\handlers\exception.py", line 55, in inner
    response = get_response(request)
               ^^^^^^^^^^^^^^^^^^^^^
  File "C:\Users\Nazmul\AppData\Local\Programs\Python\Python311\Lib\site-packages\django\core\handlers\base.py", line 197, in _get_response
    response = wrapped_callback(request, *callback_args, **callback_kwargs)
               ^^^^^^^^^^^^^^^^^^^^^^^^^^^^^^^^^^^^^^^^^^^^^^^^^^^^^^^^^^^^
  File "C:\Users\Nazmul\AppData\Local\Programs\Python\Python311\Lib\site-packages\django\views\decorators\csrf.py", line 65, in _view_wrapper
    return view_func(request, *args, **kwargs)
           ^^^^^^^^^^^^^^^^^^^^^^^^^^^^^^^^^^^
  File "C:\Users\Nazmul\AppData\Local\Programs\Python\Python311\Lib\site-packages\django\views\generic\base.py", line 105, in view
    return self.dispatch(request, *args, **kwargs)
           ^^^^^^^^^^^^^^^^^^^^^^^^^^^^^^^^^^^^^^^
  File "C:\Users\Nazmul\AppData\Local\Programs\Python\Python311\Lib\site-packages\rest_framework\views.py", line 515, in dispatch
    response = self.handle_exception(exc)
               ^^^^^^^^^^^^^^^^^^^^^^^^^^
  File "C:\Users\Nazmul\AppData\Local\Programs\Python\Python311\Lib\site-packages\rest_framework\views.py", line 475, in handle_exception
    self.raise_uncaught_exception(exc)
  File "C:\Users\Nazmul\AppData\Local\Programs\Python\Python311\Lib\site-packages\rest_framework\views.py", line 486, in raise_uncaught_exception
    raise exc
  File "C:\Users\Nazmul\AppData\Local\Programs\Python\Python311\Lib\site-packages\rest_framework\views.py", line 512, in dispatch
    response = handler(request, *args, **kwargs)
               ^^^^^^^^^^^^^^^^^^^^^^^^^^^^^^^^^
  File "C:\Users\Nazmul\Desktop\chatbot\api\views.py", line 92, in post
    except genai.types.APIError as e:
           ^^^^^^^^^^^^^^^^^^^^
AttributeError: module 'google.generativeai.types' has no attribute 'APIError'
Sending query to Gemini API: fdfd
Internal Server Error: /api/chat/
Traceback (most recent call last):
  File "C:\Users\Nazmul\Desktop\chatbot\api\views.py", line 66, in post
    response = GEMINI_MODEL.generate_content(user_query)
               ^^^^^^^^^^^^^^^^^^^^^^^^^^^^^^^^^^^^^^^^^
  File "C:\Users\Nazmul\AppData\Local\Programs\Python\Python311\Lib\site-packages\google\generativeai\generative_models.py", line 331, in generate_content
    response = self._client.generate_content(
               ^^^^^^^^^^^^^^^^^^^^^^^^^^^^^^
  File "C:\Users\Nazmul\AppData\Local\Programs\Python\Python311\Lib\site-packages\google\ai\generativelanguage_v1beta\services\generative_service\client.py", line 835, in generate_content
    response = rpc(
               ^^^^
  File "C:\Users\Nazmul\AppData\Local\Programs\Python\Python311\Lib\site-packages\google\api_core\gapic_v1\method.py", line 131, in __call__
    return wrapped_func(*args, **kwargs)
           ^^^^^^^^^^^^^^^^^^^^^^^^^^^^^
  File "C:\Users\Nazmul\AppData\Local\Programs\Python\Python311\Lib\site-packages\google\api_core\retry\retry_unary.py", line 294, in retry_wrapped_func
    return retry_target(
           ^^^^^^^^^^^^^
  File "C:\Users\Nazmul\AppData\Local\Programs\Python\Python311\Lib\site-packages\google\api_core\retry\retry_unary.py", line 156, in retry_target
    next_sleep = _retry_error_helper(
                 ^^^^^^^^^^^^^^^^^^^^
  File "C:\Users\Nazmul\AppData\Local\Programs\Python\Python311\Lib\site-packages\google\api_core\retry\retry_base.py", line 214, in _retry_error_helper
    raise final_exc from source_exc
  File "C:\Users\Nazmul\AppData\Local\Programs\Python\Python311\Lib\site-packages\google\api_core\retry\retry_unary.py", line 147, in retry_target
    result = target()
             ^^^^^^^^
  File "C:\Users\Nazmul\AppData\Local\Programs\Python\Python311\Lib\site-packages\google\api_core\timeout.py", line 130, in func_with_timeout
    return func(*args, **kwargs)
           ^^^^^^^^^^^^^^^^^^^^^
  File "C:\Users\Nazmul\AppData\Local\Programs\Python\Python311\Lib\site-packages\google\api_core\grpc_helpers.py", line 78, in error_remapped_callable
    raise exceptions.from_grpc_error(exc) from exc
google.api_core.exceptions.NotFound: 404 models/gemini-pro is not found for API version v1beta, or is not supported for generateContent. Call ListModels to see the list of available models and their supported methods.

During handling of the above exception, another exception occurred:

Traceback (most recent call last):
  File "C:\Users\Nazmul\AppData\Local\Programs\Python\Python311\Lib\site-packages\django\core\handlers\exception.py", line 55, in inner
    response = get_response(request)
               ^^^^^^^^^^^^^^^^^^^^^
  File "C:\Users\Nazmul\AppData\Local\Programs\Python\Python311\Lib\site-packages\django\core\handlers\base.py", line 197, in _get_response
    response = wrapped_callback(request, *callback_args, **callback_kwargs)
               ^^^^^^^^^^^^^^^^^^^^^^^^^^^^^^^^^^^^^^^^^^^^^^^^^^^^^^^^^^^^
  File "C:\Users\Nazmul\AppData\Local\Programs\Python\Python311\Lib\site-packages\django\views\decorators\csrf.py", line 65, in _view_wrapper
    return view_func(request, *args, **kwargs)
           ^^^^^^^^^^^^^^^^^^^^^^^^^^^^^^^^^^^
  File "C:\Users\Nazmul\AppData\Local\Programs\Python\Python311\Lib\site-packages\django\views\generic\base.py", line 105, in view
    return self.dispatch(request, *args, **kwargs)
           ^^^^^^^^^^^^^^^^^^^^^^^^^^^^^^^^^^^^^^^
  File "C:\Users\Nazmul\AppData\Local\Programs\Python\Python311\Lib\site-packages\rest_framework\views.py", line 515, in dispatch
    response = self.handle_exception(exc)
               ^^^^^^^^^^^^^^^^^^^^^^^^^^
  File "C:\Users\Nazmul\AppData\Local\Programs\Python\Python311\Lib\site-packages\rest_framework\views.py", line 475, in handle_exception
    self.raise_uncaught_exception(exc)
  File "C:\Users\Nazmul\AppData\Local\Programs\Python\Python311\Lib\site-packages\rest_framework\views.py", line 486, in raise_uncaught_exception
    raise exc
  File "C:\Users\Nazmul\AppData\Local\Programs\Python\Python311\Lib\site-packages\rest_framework\views.py", line 512, in dispatch
    response = handler(request, *args, **kwargs)
               ^^^^^^^^^^^^^^^^^^^^^^^^^^^^^^^^^
  File "C:\Users\Nazmul\Desktop\chatbot\api\views.py", line 92, in post
    except genai.types.APIError as e:
           ^^^^^^^^^^^^^^^^^^^^
AttributeError: module 'google.generativeai.types' has no attribute 'APIError'
Watching for file changes with StatReloader
Watching for file changes with StatReloader
Sending query to Gemini API: python
Internal Server Error: /api/chat/
Traceback (most recent call last):
  File "C:\Users\Nazmul\Desktop\chatbot\api\views.py", line 66, in post
    response = GEMINI_MODEL.generate_content(user_query)
               ^^^^^^^^^^^^^^^^^^^^^^^^^^^^^^^^^^^^^^^^^
  File "C:\Users\Nazmul\AppData\Local\Programs\Python\Python311\Lib\site-packages\google\generativeai\generative_models.py", line 331, in generate_content
    response = self._client.generate_content(
               ^^^^^^^^^^^^^^^^^^^^^^^^^^^^^^
  File "C:\Users\Nazmul\AppData\Local\Programs\Python\Python311\Lib\site-packages\google\ai\generativelanguage_v1beta\services\generative_service\client.py", line 835, in generate_content
    response = rpc(
               ^^^^
  File "C:\Users\Nazmul\AppData\Local\Programs\Python\Python311\Lib\site-packages\google\api_core\gapic_v1\method.py", line 131, in __call__
    return wrapped_func(*args, **kwargs)
           ^^^^^^^^^^^^^^^^^^^^^^^^^^^^^
  File "C:\Users\Nazmul\AppData\Local\Programs\Python\Python311\Lib\site-packages\google\api_core\retry\retry_unary.py", line 294, in retry_wrapped_func
    return retry_target(
           ^^^^^^^^^^^^^
  File "C:\Users\Nazmul\AppData\Local\Programs\Python\Python311\Lib\site-packages\google\api_core\retry\retry_unary.py", line 156, in retry_target
    next_sleep = _retry_error_helper(
                 ^^^^^^^^^^^^^^^^^^^^
  File "C:\Users\Nazmul\AppData\Local\Programs\Python\Python311\Lib\site-packages\google\api_core\retry\retry_base.py", line 214, in _retry_error_helper
    raise final_exc from source_exc
  File "C:\Users\Nazmul\AppData\Local\Programs\Python\Python311\Lib\site-packages\google\api_core\retry\retry_unary.py", line 147, in retry_target
    result = target()
             ^^^^^^^^
  File "C:\Users\Nazmul\AppData\Local\Programs\Python\Python311\Lib\site-packages\google\api_core\timeout.py", line 130, in func_with_timeout
    return func(*args, **kwargs)
           ^^^^^^^^^^^^^^^^^^^^^
  File "C:\Users\Nazmul\AppData\Local\Programs\Python\Python311\Lib\site-packages\google\api_core\grpc_helpers.py", line 78, in error_remapped_callable
    raise exceptions.from_grpc_error(exc) from exc
google.api_core.exceptions.NotFound: 404 models/gemini-pro is not found for API version v1beta, or is not supported for generateContent. Call ListModels to see the list of available models and their supported methods.

During handling of the above exception, another exception occurred:

Traceback (most recent call last):
  File "C:\Users\Nazmul\AppData\Local\Programs\Python\Python311\Lib\site-packages\django\core\handlers\exception.py", line 55, in inner
    response = get_response(request)
               ^^^^^^^^^^^^^^^^^^^^^
  File "C:\Users\Nazmul\AppData\Local\Programs\Python\Python311\Lib\site-packages\django\core\handlers\base.py", line 197, in _get_response
    response = wrapped_callback(request, *callback_args, **callback_kwargs)
               ^^^^^^^^^^^^^^^^^^^^^^^^^^^^^^^^^^^^^^^^^^^^^^^^^^^^^^^^^^^^
  File "C:\Users\Nazmul\AppData\Local\Programs\Python\Python311\Lib\site-packages\django\views\decorators\csrf.py", line 65, in _view_wrapper
    return view_func(request, *args, **kwargs)
           ^^^^^^^^^^^^^^^^^^^^^^^^^^^^^^^^^^^
  File "C:\Users\Nazmul\AppData\Local\Programs\Python\Python311\Lib\site-packages\django\views\generic\base.py", line 105, in view
    return self.dispatch(request, *args, **kwargs)
           ^^^^^^^^^^^^^^^^^^^^^^^^^^^^^^^^^^^^^^^
  File "C:\Users\Nazmul\AppData\Local\Programs\Python\Python311\Lib\site-packages\rest_framework\views.py", line 515, in dispatch
    response = self.handle_exception(exc)
               ^^^^^^^^^^^^^^^^^^^^^^^^^^
  File "C:\Users\Nazmul\AppData\Local\Programs\Python\Python311\Lib\site-packages\rest_framework\views.py", line 475, in handle_exception
    self.raise_uncaught_exception(exc)
  File "C:\Users\Nazmul\AppData\Local\Programs\Python\Python311\Lib\site-packages\rest_framework\views.py", line 486, in raise_uncaught_exception
    raise exc
  File "C:\Users\Nazmul\AppData\Local\Programs\Python\Python311\Lib\site-packages\rest_framework\views.py", line 512, in dispatch
    response = handler(request, *args, **kwargs)
               ^^^^^^^^^^^^^^^^^^^^^^^^^^^^^^^^^
  File "C:\Users\Nazmul\Desktop\chatbot\api\views.py", line 92, in post
    except genai.types.APIError as e:
           ^^^^^^^^^^^^^^^^^^^^
AttributeError: module 'google.generativeai.types' has no attribute 'APIError'
Watching for file changes with StatReloader
Not Found: /favicon.ico
Unauthorized: /api/chat/history/
Internal Server Error: /api/token/refresh/
Traceback (most recent call last):
  File "C:\Users\Nazmul\AppData\Local\Programs\Python\Python311\Lib\site-packages\django\core\handlers\exception.py", line 55, in inner
    response = get_response(request)
               ^^^^^^^^^^^^^^^^^^^^^
  File "C:\Users\Nazmul\AppData\Local\Programs\Python\Python311\Lib\site-packages\django\core\handlers\base.py", line 197, in _get_response
    response = wrapped_callback(request, *callback_args, **callback_kwargs)
               ^^^^^^^^^^^^^^^^^^^^^^^^^^^^^^^^^^^^^^^^^^^^^^^^^^^^^^^^^^^^
  File "C:\Users\Nazmul\AppData\Local\Programs\Python\Python311\Lib\site-packages\django\views\decorators\csrf.py", line 65, in _view_wrapper
    return view_func(request, *args, **kwargs)
           ^^^^^^^^^^^^^^^^^^^^^^^^^^^^^^^^^^^
  File "C:\Users\Nazmul\AppData\Local\Programs\Python\Python311\Lib\site-packages\django\views\generic\base.py", line 105, in view
    return self.dispatch(request, *args, **kwargs)
           ^^^^^^^^^^^^^^^^^^^^^^^^^^^^^^^^^^^^^^^
  File "C:\Users\Nazmul\AppData\Local\Programs\Python\Python311\Lib\site-packages\rest_framework\views.py", line 515, in dispatch
    response = self.handle_exception(exc)
               ^^^^^^^^^^^^^^^^^^^^^^^^^^
  File "C:\Users\Nazmul\AppData\Local\Programs\Python\Python311\Lib\site-packages\rest_framework\views.py", line 475, in handle_exception
    self.raise_uncaught_exception(exc)
  File "C:\Users\Nazmul\AppData\Local\Programs\Python\Python311\Lib\site-packages\rest_framework\views.py", line 486, in raise_uncaught_exception
    raise exc
  File "C:\Users\Nazmul\AppData\Local\Programs\Python\Python311\Lib\site-packages\rest_framework\views.py", line 512, in dispatch
    response = handler(request, *args, **kwargs)
               ^^^^^^^^^^^^^^^^^^^^^^^^^^^^^^^^^
  File "C:\Users\Nazmul\AppData\Local\Programs\Python\Python311\Lib\site-packages\rest_framework_simplejwt\views.py", line 44, in post
    serializer.is_valid(raise_exception=True)
  File "C:\Users\Nazmul\AppData\Local\Programs\Python\Python311\Lib\site-packages\rest_framework\serializers.py", line 225, in is_valid
    self._validated_data = self.run_validation(self.initial_data)
                           ^^^^^^^^^^^^^^^^^^^^^^^^^^^^^^^^^^^^^^
  File "C:\Users\Nazmul\AppData\Local\Programs\Python\Python311\Lib\site-packages\rest_framework\serializers.py", line 447, in run_validation
    value = self.validate(value)
            ^^^^^^^^^^^^^^^^^^^^
  File "C:\Users\Nazmul\AppData\Local\Programs\Python\Python311\Lib\site-packages\rest_framework_simplejwt\serializers.py", line 141, in validate
    refresh.outstand()
  File "C:\Users\Nazmul\AppData\Local\Programs\Python\Python311\Lib\site-packages\rest_framework_simplejwt\tokens.py", line 222, in outstand
    return OutstandingToken.objects.get_or_create(
           ^^^^^^^^^^^^^^^^^^^^^^^^
AttributeError: type object 'OutstandingToken' has no attribute 'objects'
Sending query to Gemini API: hai
Internal Server Error: /api/chat/
Traceback (most recent call last):
  File "C:\Users\Nazmul\Desktop\chatbot\api\views.py", line 66, in post
    response = GEMINI_MODEL.generate_content(user_query)
               ^^^^^^^^^^^^^^^^^^^^^^^^^^^^^^^^^^^^^^^^^
  File "C:\Users\Nazmul\AppData\Local\Programs\Python\Python311\Lib\site-packages\google\generativeai\generative_models.py", line 331, in generate_content
    response = self._client.generate_content(
               ^^^^^^^^^^^^^^^^^^^^^^^^^^^^^^
  File "C:\Users\Nazmul\AppData\Local\Programs\Python\Python311\Lib\site-packages\google\ai\generativelanguage_v1beta\services\generative_service\client.py", line 835, in generate_content
    response = rpc(
               ^^^^
  File "C:\Users\Nazmul\AppData\Local\Programs\Python\Python311\Lib\site-packages\google\api_core\gapic_v1\method.py", line 131, in __call__
    return wrapped_func(*args, **kwargs)
           ^^^^^^^^^^^^^^^^^^^^^^^^^^^^^
  File "C:\Users\Nazmul\AppData\Local\Programs\Python\Python311\Lib\site-packages\google\api_core\retry\retry_unary.py", line 294, in retry_wrapped_func
    return retry_target(
           ^^^^^^^^^^^^^
  File "C:\Users\Nazmul\AppData\Local\Programs\Python\Python311\Lib\site-packages\google\api_core\retry\retry_unary.py", line 156, in retry_target
    next_sleep = _retry_error_helper(
                 ^^^^^^^^^^^^^^^^^^^^
  File "C:\Users\Nazmul\AppData\Local\Programs\Python\Python311\Lib\site-packages\google\api_core\retry\retry_base.py", line 214, in _retry_error_helper
    raise final_exc from source_exc
  File "C:\Users\Nazmul\AppData\Local\Programs\Python\Python311\Lib\site-packages\google\api_core\retry\retry_unary.py", line 147, in retry_target
    result = target()
             ^^^^^^^^
  File "C:\Users\Nazmul\AppData\Local\Programs\Python\Python311\Lib\site-packages\google\api_core\timeout.py", line 130, in func_with_timeout
    return func(*args, **kwargs)
           ^^^^^^^^^^^^^^^^^^^^^
  File "C:\Users\Nazmul\AppData\Local\Programs\Python\Python311\Lib\site-packages\google\api_core\grpc_helpers.py", line 78, in error_remapped_callable
    raise exceptions.from_grpc_error(exc) from exc
google.api_core.exceptions.NotFound: 404 models/gemini-pro is not found for API version v1beta, or is not supported for generateContent. Call ListModels to see the list of available models and their supported methods.

During handling of the above exception, another exception occurred:

Traceback (most recent call last):
  File "C:\Users\Nazmul\AppData\Local\Programs\Python\Python311\Lib\site-packages\django\core\handlers\exception.py", line 55, in inner
    response = get_response(request)
               ^^^^^^^^^^^^^^^^^^^^^
  File "C:\Users\Nazmul\AppData\Local\Programs\Python\Python311\Lib\site-packages\django\core\handlers\base.py", line 197, in _get_response
    response = wrapped_callback(request, *callback_args, **callback_kwargs)
               ^^^^^^^^^^^^^^^^^^^^^^^^^^^^^^^^^^^^^^^^^^^^^^^^^^^^^^^^^^^^
  File "C:\Users\Nazmul\AppData\Local\Programs\Python\Python311\Lib\site-packages\django\views\decorators\csrf.py", line 65, in _view_wrapper
    return view_func(request, *args, **kwargs)
           ^^^^^^^^^^^^^^^^^^^^^^^^^^^^^^^^^^^
  File "C:\Users\Nazmul\AppData\Local\Programs\Python\Python311\Lib\site-packages\django\views\generic\base.py", line 105, in view
    return self.dispatch(request, *args, **kwargs)
           ^^^^^^^^^^^^^^^^^^^^^^^^^^^^^^^^^^^^^^^
  File "C:\Users\Nazmul\AppData\Local\Programs\Python\Python311\Lib\site-packages\rest_framework\views.py", line 515, in dispatch
    response = self.handle_exception(exc)
               ^^^^^^^^^^^^^^^^^^^^^^^^^^
  File "C:\Users\Nazmul\AppData\Local\Programs\Python\Python311\Lib\site-packages\rest_framework\views.py", line 475, in handle_exception
    self.raise_uncaught_exception(exc)
  File "C:\Users\Nazmul\AppData\Local\Programs\Python\Python311\Lib\site-packages\rest_framework\views.py", line 486, in raise_uncaught_exception
    raise exc
  File "C:\Users\Nazmul\AppData\Local\Programs\Python\Python311\Lib\site-packages\rest_framework\views.py", line 512, in dispatch
    response = handler(request, *args, **kwargs)
               ^^^^^^^^^^^^^^^^^^^^^^^^^^^^^^^^^
  File "C:\Users\Nazmul\Desktop\chatbot\api\views.py", line 92, in post
    except genai.types.APIError as e:
           ^^^^^^^^^^^^^^^^^^^^
AttributeError: module 'google.generativeai.types' has no attribute 'APIError'
Unauthorized: /api/chat/
Unauthorized: /api/chat/
C:\Users\Nazmul\Desktop\chatbot\api\views.py changed, reloading.
Watching for file changes with StatReloader
Internal Server Error: /api/chat/
Traceback (most recent call last):
  File "C:\Users\Nazmul\Desktop\chatbot\api\views.py", line 66, in post
    response = GEMINI_MODEL.generate_content(user_query)
               ^^^^^^^^^^^^^^^^^^^^^^^^^^^^^^^^^^^^^^^^^
  File "C:\Users\Nazmul\AppData\Local\Programs\Python\Python311\Lib\site-packages\google\generativeai\generative_models.py", line 331, in generate_content
    response = self._client.generate_content(
               ^^^^^^^^^^^^^^^^^^^^^^^^^^^^^^
  File "C:\Users\Nazmul\AppData\Local\Programs\Python\Python311\Lib\site-packages\google\ai\generativelanguage_v1beta\services\generative_service\client.py", line 835, in generate_content
    response = rpc(
               ^^^^
  File "C:\Users\Nazmul\AppData\Local\Programs\Python\Python311\Lib\site-packages\google\api_core\gapic_v1\method.py", line 131, in __call__
    return wrapped_func(*args, **kwargs)
           ^^^^^^^^^^^^^^^^^^^^^^^^^^^^^
  File "C:\Users\Nazmul\AppData\Local\Programs\Python\Python311\Lib\site-packages\google\api_core\retry\retry_unary.py", line 294, in retry_wrapped_func
    return retry_target(
           ^^^^^^^^^^^^^
  File "C:\Users\Nazmul\AppData\Local\Programs\Python\Python311\Lib\site-packages\google\api_core\retry\retry_unary.py", line 156, in retry_target
    next_sleep = _retry_error_helper(
                 ^^^^^^^^^^^^^^^^^^^^
  File "C:\Users\Nazmul\AppData\Local\Programs\Python\Python311\Lib\site-packages\google\api_core\retry\retry_base.py", line 214, in _retry_error_helper
    raise final_exc from source_exc
  File "C:\Users\Nazmul\AppData\Local\Programs\Python\Python311\Lib\site-packages\google\api_core\retry\retry_unary.py", line 147, in retry_target
    result = target()
             ^^^^^^^^
  File "C:\Users\Nazmul\AppData\Local\Programs\Python\Python311\Lib\site-packages\google\api_core\timeout.py", line 130, in func_with_timeout
    return func(*args, **kwargs)
           ^^^^^^^^^^^^^^^^^^^^^
  File "C:\Users\Nazmul\AppData\Local\Programs\Python\Python311\Lib\site-packages\google\api_core\grpc_helpers.py", line 78, in error_remapped_callable
    raise exceptions.from_grpc_error(exc) from exc
google.api_core.exceptions.NotFound: 404 models/gemini-pro is not found for API version v1beta, or is not supported for generateContent. Call ListModels to see the list of available models and their supported methods.

During handling of the above exception, another exception occurred:

Traceback (most recent call last):
  File "C:\Users\Nazmul\AppData\Local\Programs\Python\Python311\Lib\site-packages\django\core\handlers\exception.py", line 55, in inner
    response = get_response(request)
               ^^^^^^^^^^^^^^^^^^^^^
  File "C:\Users\Nazmul\AppData\Local\Programs\Python\Python311\Lib\site-packages\django\core\handlers\base.py", line 197, in _get_response
    response = wrapped_callback(request, *callback_args, **callback_kwargs)
               ^^^^^^^^^^^^^^^^^^^^^^^^^^^^^^^^^^^^^^^^^^^^^^^^^^^^^^^^^^^^
  File "C:\Users\Nazmul\AppData\Local\Programs\Python\Python311\Lib\site-packages\django\views\decorators\csrf.py", line 65, in _view_wrapper
    return view_func(request, *args, **kwargs)
           ^^^^^^^^^^^^^^^^^^^^^^^^^^^^^^^^^^^
  File "C:\Users\Nazmul\AppData\Local\Programs\Python\Python311\Lib\site-packages\django\views\generic\base.py", line 105, in view
    return self.dispatch(request, *args, **kwargs)
           ^^^^^^^^^^^^^^^^^^^^^^^^^^^^^^^^^^^^^^^
  File "C:\Users\Nazmul\AppData\Local\Programs\Python\Python311\Lib\site-packages\rest_framework\views.py", line 515, in dispatch
    response = self.handle_exception(exc)
               ^^^^^^^^^^^^^^^^^^^^^^^^^^
  File "C:\Users\Nazmul\AppData\Local\Programs\Python\Python311\Lib\site-packages\rest_framework\views.py", line 475, in handle_exception
    self.raise_uncaught_exception(exc)
  File "C:\Users\Nazmul\AppData\Local\Programs\Python\Python311\Lib\site-packages\rest_framework\views.py", line 486, in raise_uncaught_exception
    raise exc
  File "C:\Users\Nazmul\AppData\Local\Programs\Python\Python311\Lib\site-packages\rest_framework\views.py", line 512, in dispatch
    response = handler(request, *args, **kwargs)
               ^^^^^^^^^^^^^^^^^^^^^^^^^^^^^^^^^
  File "C:\Users\Nazmul\Desktop\chatbot\api\views.py", line 94, in post
    except genai.APIError as e:
          ^^^^^^^^^^^^^^
AttributeError: module 'google.generativeai' has no attribute 'APIError'
C:\Users\Nazmul\Desktop\chatbot\api\views.py changed, reloading.
Watching for file changes with StatReloader
Gemini API Call Error: 404 models/gemini-pro is not found for API version v1beta, or is not supported for generateContent. Call ListModels to see the list of available models and their supported methods.
Traceback (most recent call last):
  File "C:\Users\Nazmul\Desktop\chatbot\api\views.py", line 62, in post
    response = GEMINI_MODEL.generate_content(user_query)
               ^^^^^^^^^^^^^^^^^^^^^^^^^^^^^^^^^^^^^^^^^
  File "C:\Users\Nazmul\AppData\Local\Programs\Python\Python311\Lib\site-packages\google\generativeai\generative_models.py", line 331, in generate_content
    response = self._client.generate_content(
               ^^^^^^^^^^^^^^^^^^^^^^^^^^^^^^
  File "C:\Users\Nazmul\AppData\Local\Programs\Python\Python311\Lib\site-packages\google\ai\generativelanguage_v1beta\services\generative_service\client.py", line 835, in generate_content
    response = rpc(
               ^^^^
  File "C:\Users\Nazmul\AppData\Local\Programs\Python\Python311\Lib\site-packages\google\api_core\gapic_v1\method.py", line 131, in __call__
    return wrapped_func(*args, **kwargs)
           ^^^^^^^^^^^^^^^^^^^^^^^^^^^^^
  File "C:\Users\Nazmul\AppData\Local\Programs\Python\Python311\Lib\site-packages\google\api_core\retry\retry_unary.py", line 294, in retry_wrapped_func
    return retry_target(
           ^^^^^^^^^^^^^
  File "C:\Users\Nazmul\AppData\Local\Programs\Python\Python311\Lib\site-packages\google\api_core\retry\retry_unary.py", line 156, in retry_target
    next_sleep = _retry_error_helper(
                 ^^^^^^^^^^^^^^^^^^^^
  File "C:\Users\Nazmul\AppData\Local\Programs\Python\Python311\Lib\site-packages\google\api_core\retry\retry_base.py", line 214, in _retry_error_helper
    raise final_exc from source_exc
  File "C:\Users\Nazmul\AppData\Local\Programs\Python\Python311\Lib\site-packages\google\api_core\retry\retry_unary.py", line 147, in retry_target
    result = target()
             ^^^^^^^^
  File "C:\Users\Nazmul\AppData\Local\Programs\Python\Python311\Lib\site-packages\google\api_core\timeout.py", line 130, in func_with_timeout
    return func(*args, **kwargs)
           ^^^^^^^^^^^^^^^^^^^^^
  File "C:\Users\Nazmul\AppData\Local\Programs\Python\Python311\Lib\site-packages\google\api_core\grpc_helpers.py", line 78, in error_remapped_callable
    raise exceptions.from_grpc_error(exc) from exc
google.api_core.exceptions.NotFound: 404 models/gemini-pro is not found for API version v1beta, or is not supported for generateContent. Call ListModels to see the list of available models and their supported methods.
Internal Server Error: /api/chat/
C:\Users\Nazmul\Desktop\chatbot\api\views.py changed, reloading.
Watching for file changes with StatReloader
C:\Users\Nazmul\Desktop\chatbot\project\settings.py changed, reloading.
Watching for file changes with StatReloader
Watching for file changes with StatReloader
C:\Users\Nazmul\Desktop\chatbot\project\settings.py changed, reloading.
Watching for file changes with StatReloader
Gemini API Call Error: 404 models/gemini-pro is not found for API version v1beta, or is not supported for generateContent. Call ListModels to see the list of available models and their supported methods.
Traceback (most recent call last):
  File "C:\Users\Nazmul\Desktop\chatbot\api\views.py", line 94, in post
    response = GEMINI_MODEL.generate_content(user_query)
               ^^^^^^^^^^^^^^^^^^^^^^^^^^^^^^^^^^^^^^^^^
  File "C:\Users\Nazmul\AppData\Local\Programs\Python\Python311\Lib\site-packages\google\generativeai\generative_models.py", line 331, in generate_content
    response = self._client.generate_content(
               ^^^^^^^^^^^^^^^^^^^^^^^^^^^^^^
  File "C:\Users\Nazmul\AppData\Local\Programs\Python\Python311\Lib\site-packages\google\ai\generativelanguage_v1beta\services\generative_service\client.py", line 835, in generate_content
    response = rpc(
               ^^^^
  File "C:\Users\Nazmul\AppData\Local\Programs\Python\Python311\Lib\site-packages\google\api_core\gapic_v1\method.py", line 131, in __call__
    return wrapped_func(*args, **kwargs)
           ^^^^^^^^^^^^^^^^^^^^^^^^^^^^^
  File "C:\Users\Nazmul\AppData\Local\Programs\Python\Python311\Lib\site-packages\google\api_core\retry\retry_unary.py", line 294, in retry_wrapped_func
    return retry_target(
           ^^^^^^^^^^^^^
  File "C:\Users\Nazmul\AppData\Local\Programs\Python\Python311\Lib\site-packages\google\api_core\retry\retry_unary.py", line 156, in retry_target
    next_sleep = _retry_error_helper(
                 ^^^^^^^^^^^^^^^^^^^^
  File "C:\Users\Nazmul\AppData\Local\Programs\Python\Python311\Lib\site-packages\google\api_core\retry\retry_base.py", line 214, in _retry_error_helper
    raise final_exc from source_exc
  File "C:\Users\Nazmul\AppData\Local\Programs\Python\Python311\Lib\site-packages\google\api_core\retry\retry_unary.py", line 147, in retry_target
    result = target()
             ^^^^^^^^
  File "C:\Users\Nazmul\AppData\Local\Programs\Python\Python311\Lib\site-packages\google\api_core\timeout.py", line 130, in func_with_timeout
    return func(*args, **kwargs)
           ^^^^^^^^^^^^^^^^^^^^^
  File "C:\Users\Nazmul\AppData\Local\Programs\Python\Python311\Lib\site-packages\google\api_core\grpc_helpers.py", line 78, in error_remapped_callable
    raise exceptions.from_grpc_error(exc) from exc
google.api_core.exceptions.NotFound: 404 models/gemini-pro is not found for API version v1beta, or is not supported for generateContent. Call ListModels to see the list of available models and their supported methods.
Internal Server Error: /api/chat/
Watching for file changes with StatReloader
Gemini API Call Error: 404 models/gemini-pro is not found for API version v1beta, or is not supported for generateContent. Call ListModels to see the list of available models and their supported methods.
Traceback (most recent call last):
  File "C:\Users\Nazmul\Desktop\chatbot\api\views.py", line 94, in post
    response = GEMINI_MODEL.generate_content(user_query)
               ^^^^^^^^^^^^^^^^^^^^^^^^^^^^^^^^^^^^^^^^^
  File "C:\Users\Nazmul\AppData\Local\Programs\Python\Python311\Lib\site-packages\google\generativeai\generative_models.py", line 331, in generate_content
    response = self._client.generate_content(
               ^^^^^^^^^^^^^^^^^^^^^^^^^^^^^^
  File "C:\Users\Nazmul\AppData\Local\Programs\Python\Python311\Lib\site-packages\google\ai\generativelanguage_v1beta\services\generative_service\client.py", line 835, in generate_content
    response = rpc(
               ^^^^
  File "C:\Users\Nazmul\AppData\Local\Programs\Python\Python311\Lib\site-packages\google\api_core\gapic_v1\method.py", line 131, in __call__
    return wrapped_func(*args, **kwargs)
           ^^^^^^^^^^^^^^^^^^^^^^^^^^^^^
  File "C:\Users\Nazmul\AppData\Local\Programs\Python\Python311\Lib\site-packages\google\api_core\retry\retry_unary.py", line 294, in retry_wrapped_func
    return retry_target(
           ^^^^^^^^^^^^^
  File "C:\Users\Nazmul\AppData\Local\Programs\Python\Python311\Lib\site-packages\google\api_core\retry\retry_unary.py", line 156, in retry_target
    next_sleep = _retry_error_helper(
                 ^^^^^^^^^^^^^^^^^^^^
  File "C:\Users\Nazmul\AppData\Local\Programs\Python\Python311\Lib\site-packages\google\api_core\retry\retry_base.py", line 214, in _retry_error_helper
    raise final_exc from source_exc
  File "C:\Users\Nazmul\AppData\Local\Programs\Python\Python311\Lib\site-packages\google\api_core\retry\retry_unary.py", line 147, in retry_target
    result = target()
             ^^^^^^^^
  File "C:\Users\Nazmul\AppData\Local\Programs\Python\Python311\Lib\site-packages\google\api_core\timeout.py", line 130, in func_with_timeout
    return func(*args, **kwargs)
           ^^^^^^^^^^^^^^^^^^^^^
  File "C:\Users\Nazmul\AppData\Local\Programs\Python\Python311\Lib\site-packages\google\api_core\grpc_helpers.py", line 78, in error_remapped_callable
    raise exceptions.from_grpc_error(exc) from exc
google.api_core.exceptions.NotFound: 404 models/gemini-pro is not found for API version v1beta, or is not supported for generateContent. Call ListModels to see the list of available models and their supported methods.
Internal Server Error: /api/chat/
Watching for file changes with StatReloader
Chat interaction saved for user: nazmul
Chat interaction saved for user: nazmul
Chat interaction saved for user: nazmul
Chat interaction saved for user: nazmul
Chat interaction saved for user: nazmul
Chat interaction saved for user: nazmul
Chat interaction saved for user: nazmul
Chat interaction saved for user: nazmul
Chat interaction saved for user: nazmul
Watching for file changes with StatReloader
Chat interaction saved for user: nazmul
Chat interaction saved for user: nazmul
Chat interaction saved for user: nazmul
C:\Users\Nazmul\Desktop\chatbot\project\settings.py changed, reloading.
INFO 2025-07-02 07:21:49,918 autoreload 11692 5564 Watching for file changes with StatReloader
INFO 2025-07-02 07:22:03,369 basehttp 11692 21296 "GET / HTTP/1.1" 200 16560
INFO 2025-07-02 07:22:03,485 basehttp 11692 21296 "GET /api/chat/history/ HTTP/1.1" 200 19058
INFO 2025-07-02 07:22:09,442 views 11692 21296 Chat interaction saved for user: nazmul
INFO 2025-07-02 07:22:09,442 basehttp 11692 21296 "POST /api/chat/ HTTP/1.1" 200 171
INFO 2025-07-02 07:23:30,030 views 11692 5444 Sending query to Gemini API: hello
INFO 2025-07-02 07:23:30,765 views 11692 5444 Chat interaction saved for user: nazmul
INFO 2025-07-02 07:23:30,765 basehttp 11692 5444 "POST /api/chat/ HTTP/1.1" 200 122
INFO 2025-07-02 07:23:56,411 autoreload 11048 3100 Watching for file changes with StatReloader
INFO 2025-07-02 07:24:03,088 basehttp 11048 9876 "GET / HTTP/1.1" 200 16560
INFO 2025-07-02 07:24:03,396 basehttp 11048 9876 "GET /api/chat/history/ HTTP/1.1" 200 19353
INFO 2025-07-02 07:24:25,651 basehttp 11048 9876 "GET / HTTP/1.1" 200 16560
INFO 2025-07-02 07:24:25,684 basehttp 11048 9876 "GET /api/chat/history/ HTTP/1.1" 200 19353
INFO 2025-07-02 07:24:32,596 views 11048 9876 Sending query to Gemini API: hi
INFO 2025-07-02 07:24:34,751 views 11048 9876 Chat interaction saved for user: nazmul
INFO 2025-07-02 07:24:34,751 basehttp 11048 9876 "POST /api/chat/ HTTP/1.1" 200 116
INFO 2025-07-02 07:24:37,033 views 11048 9876 Sending query to Gemini API: hello
INFO 2025-07-02 07:24:37,711 views 11048 9876 Chat interaction saved for user: nazmul
INFO 2025-07-02 07:24:37,711 basehttp 11048 9876 "POST /api/chat/ HTTP/1.1" 200 122
INFO 2025-07-02 07:24:39,571 views 11048 12548 Sending query to Gemini API: hello
INFO 2025-07-02 07:24:40,184 views 11048 12548 Chat interaction saved for user: nazmul
INFO 2025-07-02 07:24:40,199 basehttp 11048 12548 "POST /api/chat/ HTTP/1.1" 200 122
INFO 2025-07-02 07:31:58,157 autoreload 11048 3100 C:\Users\Nazmul\Desktop\chatbot\project\settings.py changed, reloading.
INFO 2025-07-02 07:33:07,002 autoreload 6792 4252 Watching for file changes with StatReloader
INFO 2025-07-02 07:33:31,135 views 6792 18272 Sending query to Gemini API: hai
INFO 2025-07-02 07:33:33,744 views 6792 18272 Chat interaction saved for user: nazmul
INFO 2025-07-02 07:33:33,744 basehttp 6792 18272 "POST /api/chat/ HTTP/1.1" 200 117
INFO 2025-07-02 07:41:18,209 views 6792 5472 Sending query to Gemini API: hhi
INFO 2025-07-02 07:41:20,569 views 6792 5472 Chat interaction saved for user: nazmul
INFO 2025-07-02 07:41:20,570 basehttp 6792 5472 "POST /api/chat/ HTTP/1.1" 200 140
INFO 2025-07-02 07:41:32,099 views 6792 5472 Sending query to Gemini API: himel love you
INFO 2025-07-02 07:41:33,753 views 6792 5472 Chat interaction saved for user: nazmul
INFO 2025-07-02 07:41:33,754 basehttp 6792 5472 "POST /api/chat/ HTTP/1.1" 200 157
WARNING 2025-07-02 07:44:32,505 log 6792 4400 Unauthorized: /api/chat/
WARNING 2025-07-02 07:44:32,506 basehttp 6792 4400 "POST /api/chat/ HTTP/1.1" 401 172
ERROR 2025-07-02 07:44:32,553 log 6792 4400 Internal Server Error: /api/token/refresh/
Traceback (most recent call last):
  File "C:\Users\Nazmul\AppData\Local\Programs\Python\Python311\Lib\site-packages\django\core\handlers\exception.py", line 55, in inner
    response = get_response(request)
               ^^^^^^^^^^^^^^^^^^^^^
  File "C:\Users\Nazmul\AppData\Local\Programs\Python\Python311\Lib\site-packages\django\core\handlers\base.py", line 197, in _get_response
    response = wrapped_callback(request, *callback_args, **callback_kwargs)
               ^^^^^^^^^^^^^^^^^^^^^^^^^^^^^^^^^^^^^^^^^^^^^^^^^^^^^^^^^^^^
  File "C:\Users\Nazmul\AppData\Local\Programs\Python\Python311\Lib\site-packages\django\views\decorators\csrf.py", line 65, in _view_wrapper
    return view_func(request, *args, **kwargs)
           ^^^^^^^^^^^^^^^^^^^^^^^^^^^^^^^^^^^
  File "C:\Users\Nazmul\AppData\Local\Programs\Python\Python311\Lib\site-packages\django\views\generic\base.py", line 105, in view
    return self.dispatch(request, *args, **kwargs)
           ^^^^^^^^^^^^^^^^^^^^^^^^^^^^^^^^^^^^^^^
  File "C:\Users\Nazmul\AppData\Local\Programs\Python\Python311\Lib\site-packages\rest_framework\views.py", line 515, in dispatch
    response = self.handle_exception(exc)
               ^^^^^^^^^^^^^^^^^^^^^^^^^^
  File "C:\Users\Nazmul\AppData\Local\Programs\Python\Python311\Lib\site-packages\rest_framework\views.py", line 475, in handle_exception
    self.raise_uncaught_exception(exc)
  File "C:\Users\Nazmul\AppData\Local\Programs\Python\Python311\Lib\site-packages\rest_framework\views.py", line 486, in raise_uncaught_exception
    raise exc
  File "C:\Users\Nazmul\AppData\Local\Programs\Python\Python311\Lib\site-packages\rest_framework\views.py", line 512, in dispatch
    response = handler(request, *args, **kwargs)
               ^^^^^^^^^^^^^^^^^^^^^^^^^^^^^^^^^
  File "C:\Users\Nazmul\AppData\Local\Programs\Python\Python311\Lib\site-packages\rest_framework_simplejwt\views.py", line 44, in post
    serializer.is_valid(raise_exception=True)
  File "C:\Users\Nazmul\AppData\Local\Programs\Python\Python311\Lib\site-packages\rest_framework\serializers.py", line 225, in is_valid
    self._validated_data = self.run_validation(self.initial_data)
                           ^^^^^^^^^^^^^^^^^^^^^^^^^^^^^^^^^^^^^^
  File "C:\Users\Nazmul\AppData\Local\Programs\Python\Python311\Lib\site-packages\rest_framework\serializers.py", line 447, in run_validation
    value = self.validate(value)
            ^^^^^^^^^^^^^^^^^^^^
  File "C:\Users\Nazmul\AppData\Local\Programs\Python\Python311\Lib\site-packages\rest_framework_simplejwt\serializers.py", line 141, in validate
    refresh.outstand()
  File "C:\Users\Nazmul\AppData\Local\Programs\Python\Python311\Lib\site-packages\rest_framework_simplejwt\tokens.py", line 222, in outstand
    return OutstandingToken.objects.get_or_create(
           ^^^^^^^^^^^^^^^^^^^^^^^^
AttributeError: type object 'OutstandingToken' has no attribute 'objects'
ERROR 2025-07-02 07:44:32,569 basehttp 6792 4400 "POST /api/token/refresh/ HTTP/1.1" 500 118389
INFO 2025-07-02 07:44:41,897 basehttp 6792 4400 "POST /api/token/ HTTP/1.1" 200 483
INFO 2025-07-02 07:44:41,915 basehttp 6792 4400 "GET /api/chat/history/ HTTP/1.1" 200 20133
INFO 2025-07-02 07:44:45,630 views 6792 4400 Sending query to Gemini API: hello
INFO 2025-07-02 07:44:46,315 views 6792 4400 Chat interaction saved for user: nazmul
INFO 2025-07-02 07:44:46,315 basehttp 6792 4400 "POST /api/chat/ HTTP/1.1" 200 122
INFO 2025-07-02 07:45:02,198 views 6792 4400 Sending query to Gemini API: i need some movie name
INFO 2025-07-02 07:45:03,630 views 6792 4400 Chat interaction saved for user: nazmul
INFO 2025-07-02 07:45:03,644 basehttp 6792 4400 "POST /api/chat/ HTTP/1.1" 200 622
INFO 2025-07-02 07:45:26,740 views 6792 4400 Sending query to Gemini API: give dark movie name
INFO 2025-07-02 07:45:27,881 views 6792 4400 Chat interaction saved for user: nazmul
INFO 2025-07-02 07:45:27,881 basehttp 6792 4400 "POST /api/chat/ HTTP/1.1" 200 308
INFO 2025-07-02 07:46:09,488 views 6792 4400 Sending query to Gemini API: please tell something about pyanchyat
INFO 2025-07-02 07:46:12,595 views 6792 4400 Chat interaction saved for user: nazmul
INFO 2025-07-02 07:46:12,611 basehttp 6792 4400 "POST /api/chat/ HTTP/1.1" 200 1908
INFO 2025-07-02 07:46:35,095 views 6792 4400 Sending query to Gemini API: tell something about story
INFO 2025-07-02 07:46:37,419 views 6792 4400 Chat interaction saved for user: nazmul
INFO 2025-07-02 07:46:37,420 basehttp 6792 4400 "POST /api/chat/ HTTP/1.1" 200 1438
INFO 2025-07-02 07:47:20,938 views 6792 4400 Sending query to Gemini API: please give some actors name
INFO 2025-07-02 07:47:22,957 views 6792 4400 Chat interaction saved for user: nazmul
INFO 2025-07-02 07:47:22,957 basehttp 6792 4400 "POST /api/chat/ HTTP/1.1" 200 901
INFO 2025-07-02 07:51:06,052 autoreload 16008 1200 Watching for file changes with StatReloader
INFO 2025-07-02 07:51:26,203 basehttp 16008 9780 "GET / HTTP/1.1" 200 16560
INFO 2025-07-02 07:51:26,329 basehttp 16008 9780 "GET /api/chat/history/ HTTP/1.1" 200 25438
INFO 2025-07-02 07:51:29,969 views 16008 9780 Sending query to Gemini API: hai
INFO 2025-07-02 07:51:32,161 views 16008 9780 Chat interaction saved for user: nazmul
INFO 2025-07-02 07:51:32,161 basehttp 16008 9780 "POST /api/chat/ HTTP/1.1" 200 117
INFO 2025-07-02 07:51:33,722 views 16008 9780 Sending query to Gemini API: hello
INFO 2025-07-02 07:51:34,388 views 16008 9780 Chat interaction saved for user: nazmul
INFO 2025-07-02 07:51:34,394 basehttp 16008 9780 "POST /api/chat/ HTTP/1.1" 200 122
INFO 2025-07-02 07:51:37,046 views 16008 9780 Sending query to Gemini API: baby
INFO 2025-07-02 07:51:38,486 views 16008 9780 Chat interaction saved for user: nazmul
INFO 2025-07-02 07:51:38,486 basehttp 16008 9780 "POST /api/chat/ HTTP/1.1" 200 597
INFO 2025-07-02 07:52:00,271 views 16008 9780 Sending query to Gemini API: please tell something about sparteck
INFO 2025-07-02 07:52:02,520 views 16008 9780 Chat interaction saved for user: nazmul
INFO 2025-07-02 07:52:02,520 basehttp 16008 9780 "POST /api/chat/ HTTP/1.1" 200 1171
INFO 2025-07-02 07:52:35,767 views 16008 9780 Sending query to Gemini API: do you know about bsmrstu
INFO 2025-07-02 07:52:36,683 views 16008 9780 Chat interaction saved for user: nazmul
INFO 2025-07-02 07:52:36,684 basehttp 16008 9780 "POST /api/chat/ HTTP/1.1" 200 291
INFO 2025-07-02 07:53:29,917 views 16008 9780 Sending query to Gemini API: this information is fully wrong
INFO 2025-07-02 07:53:30,731 views 16008 9780 Chat interaction saved for user: nazmul
INFO 2025-07-02 07:53:30,732 basehttp 16008 9780 "POST /api/chat/ HTTP/1.1" 200 291
INFO 2025-07-02 07:54:31,022 views 16008 9780 Sending query to Gemini API: bsmrstu stands for Bangabondhu Science and technology university gopalgang
INFO 2025-07-02 07:54:31,799 views 16008 9780 Chat interaction saved for user: nazmul
INFO 2025-07-02 07:54:31,801 basehttp 16008 9780 "POST /api/chat/ HTTP/1.1" 200 268
INFO 2025-07-02 07:55:06,627 views 16008 9780 Sending query to Gemini API: now tell me something about bsmrstu
INFO 2025-07-02 07:55:09,100 views 16008 9780 Chat interaction saved for user: nazmul
INFO 2025-07-02 07:55:09,100 basehttp 16008 9780 "POST /api/chat/ HTTP/1.1" 200 1628
INFO 2025-07-02 07:58:41,950 autoreload 16008 1200 C:\Users\Nazmul\Desktop\chatbot\project\settings.py changed, reloading.
INFO 2025-07-02 07:58:45,012 autoreload 21660 7620 Watching for file changes with StatReloader
INFO 2025-07-02 07:58:55,263 basehttp 21660 18804 "GET / HTTP/1.1" 200 16560
INFO 2025-07-02 07:58:55,407 basehttp 21660 18804 "GET /api/chat/history/ HTTP/1.1" 200 29931
INFO 2025-07-02 07:59:02,203 views 21660 11816 Sending query to Gemini API: hai
INFO 2025-07-02 07:59:05,022 views 21660 11816 Chat interaction saved for user: nazmul
INFO 2025-07-02 07:59:05,022 basehttp 21660 11816 "POST /api/chat/ HTTP/1.1" 200 117
INFO 2025-07-02 08:02:44,471 autoreload 21660 7620 C:\Users\Nazmul\Desktop\chatbot\project\settings.py changed, reloading.
INFO 2025-07-02 08:02:47,511 autoreload 12332 19712 Watching for file changes with StatReloader
INFO 2025-07-02 08:02:58,372 basehttp 12332 17056 "GET / HTTP/1.1" 200 16560
ERROR 2025-07-02 08:02:58,542 log 12332 17056 Internal Server Error: /api/chat/history/
Traceback (most recent call last):
  File "C:\Users\Nazmul\AppData\Local\Programs\Python\Python311\Lib\site-packages\django\core\handlers\exception.py", line 55, in inner
    response = get_response(request)
               ^^^^^^^^^^^^^^^^^^^^^
  File "C:\Users\Nazmul\AppData\Local\Programs\Python\Python311\Lib\site-packages\django\core\handlers\base.py", line 197, in _get_response
    response = wrapped_callback(request, *callback_args, **callback_kwargs)
               ^^^^^^^^^^^^^^^^^^^^^^^^^^^^^^^^^^^^^^^^^^^^^^^^^^^^^^^^^^^^
  File "C:\Users\Nazmul\AppData\Local\Programs\Python\Python311\Lib\site-packages\django\views\decorators\csrf.py", line 65, in _view_wrapper
    return view_func(request, *args, **kwargs)
           ^^^^^^^^^^^^^^^^^^^^^^^^^^^^^^^^^^^
  File "C:\Users\Nazmul\AppData\Local\Programs\Python\Python311\Lib\site-packages\django\views\generic\base.py", line 105, in view
    return self.dispatch(request, *args, **kwargs)
           ^^^^^^^^^^^^^^^^^^^^^^^^^^^^^^^^^^^^^^^
  File "C:\Users\Nazmul\AppData\Local\Programs\Python\Python311\Lib\site-packages\rest_framework\views.py", line 515, in dispatch
    response = self.handle_exception(exc)
               ^^^^^^^^^^^^^^^^^^^^^^^^^^
  File "C:\Users\Nazmul\AppData\Local\Programs\Python\Python311\Lib\site-packages\rest_framework\views.py", line 475, in handle_exception
    self.raise_uncaught_exception(exc)
  File "C:\Users\Nazmul\AppData\Local\Programs\Python\Python311\Lib\site-packages\rest_framework\views.py", line 486, in raise_uncaught_exception
    raise exc
  File "C:\Users\Nazmul\AppData\Local\Programs\Python\Python311\Lib\site-packages\rest_framework\views.py", line 503, in dispatch
    self.initial(request, *args, **kwargs)
  File "C:\Users\Nazmul\AppData\Local\Programs\Python\Python311\Lib\site-packages\rest_framework\views.py", line 420, in initial
    self.perform_authentication(request)
  File "C:\Users\Nazmul\AppData\Local\Programs\Python\Python311\Lib\site-packages\rest_framework\views.py", line 330, in perform_authentication
    request.user
  File "C:\Users\Nazmul\AppData\Local\Programs\Python\Python311\Lib\site-packages\rest_framework\request.py", line 232, in user
    self._authenticate()
  File "C:\Users\Nazmul\AppData\Local\Programs\Python\Python311\Lib\site-packages\rest_framework\request.py", line 385, in _authenticate
    user_auth_tuple = authenticator.authenticate(self)
                      ^^^^^^^^^^^^^^^^^^^^^^^^^^^^^^^^
  File "C:\Users\Nazmul\AppData\Local\Programs\Python\Python311\Lib\site-packages\rest_framework_simplejwt\authentication.py", line 51, in authenticate
    return self.get_user(validated_token), validated_token
           ^^^^^^^^^^^^^^^^^^^^^^^^^^^^^^
  File "C:\Users\Nazmul\AppData\Local\Programs\Python\Python311\Lib\site-packages\rest_framework_simplejwt\authentication.py", line 130, in get_user
    user = self.user_model.objects.get(**{api_settings.USER_ID_FIELD: user_id})
           ^^^^^^^^^^^^^^^^^^^^^^^^^^^^^^^^^^^^^^^^^^^^^^^^^^^^^^^^^^^^^^^^^^^^
  File "C:\Users\Nazmul\AppData\Local\Programs\Python\Python311\Lib\site-packages\django\db\models\manager.py", line 87, in manager_method
    return getattr(self.get_queryset(), name)(*args, **kwargs)
           ^^^^^^^^^^^^^^^^^^^^^^^^^^^^^^^^^^^^^^^^^^^^^^^^^^^
  File "C:\Users\Nazmul\AppData\Local\Programs\Python\Python311\Lib\site-packages\django\db\models\query.py", line 629, in get
    num = len(clone)
          ^^^^^^^^^^
  File "C:\Users\Nazmul\AppData\Local\Programs\Python\Python311\Lib\site-packages\django\db\models\query.py", line 366, in __len__
    self._fetch_all()
  File "C:\Users\Nazmul\AppData\Local\Programs\Python\Python311\Lib\site-packages\django\db\models\query.py", line 1949, in _fetch_all
    self._result_cache = list(self._iterable_class(self))
                         ^^^^^^^^^^^^^^^^^^^^^^^^^^^^^^^^
  File "C:\Users\Nazmul\AppData\Local\Programs\Python\Python311\Lib\site-packages\django\db\models\query.py", line 91, in __iter__
    results = compiler.execute_sql(
              ^^^^^^^^^^^^^^^^^^^^^
  File "C:\Users\Nazmul\AppData\Local\Programs\Python\Python311\Lib\site-packages\django\db\models\sql\compiler.py", line 1610, in execute_sql
    sql, params = self.as_sql()
                  ^^^^^^^^^^^^^
  File "C:\Users\Nazmul\AppData\Local\Programs\Python\Python311\Lib\site-packages\django\db\models\sql\compiler.py", line 766, in as_sql
    extra_select, order_by, group_by = self.pre_sql_setup(
                                       ^^^^^^^^^^^^^^^^^^^
  File "C:\Users\Nazmul\AppData\Local\Programs\Python\Python311\Lib\site-packages\django\db\models\sql\compiler.py", line 85, in pre_sql_setup
    self.setup_query(with_col_aliases=with_col_aliases)
  File "C:\Users\Nazmul\AppData\Local\Programs\Python\Python311\Lib\site-packages\django\db\models\sql\compiler.py", line 74, in setup_query
    self.select, self.klass_info, self.annotation_col_map = self.get_select(
                                                            ^^^^^^^^^^^^^^^^
  File "C:\Users\Nazmul\AppData\Local\Programs\Python\Python311\Lib\site-packages\django\db\models\sql\compiler.py", line 316, in get_select
    sql, params = self.compile(col)
                  ^^^^^^^^^^^^^^^^^
  File "C:\Users\Nazmul\AppData\Local\Programs\Python\Python311\Lib\site-packages\django\db\models\sql\compiler.py", line 577, in compile
    sql, params = node.as_sql(self, self.connection)
                  ^^^^^^^^^^^^^^^^^^^^^^^^^^^^^^^^^^
  File "C:\Users\Nazmul\AppData\Local\Programs\Python\Python311\Lib\site-packages\django\db\models\expressions.py", line 1305, in as_sql
    sql = ".".join(map(compiler.quote_name_unless_alias, identifiers))
          ^^^^^^^^^^^^^^^^^^^^^^^^^^^^^^^^^^^^^^^^^^^^^^^^^^^^^^^^^^^^
  File "C:\Users\Nazmul\AppData\Local\Programs\Python\Python311\Lib\site-packages\django\db\models\sql\compiler.py", line 568, in quote_name_unless_alias
    r = self.connection.ops.quote_name(name)
        ^^^^^^^^^^^^^^^^^^^^^^^^^^^^^^^^^^^^
  File "C:\Users\Nazmul\AppData\Local\Programs\Python\Python311\Lib\site-packages\django\db\backends\dummy\base.py", line 20, in complain
    raise ImproperlyConfigured(
django.core.exceptions.ImproperlyConfigured: settings.DATABASES is improperly configured. Please supply the ENGINE value. Check settings documentation for more details.
ERROR 2025-07-02 08:02:58,552 basehttp 12332 17056 "GET /api/chat/history/ HTTP/1.1" 500 183918
ERROR 2025-07-02 08:03:04,129 log 12332 17056 Internal Server Error: /api/chat/
Traceback (most recent call last):
  File "C:\Users\Nazmul\AppData\Local\Programs\Python\Python311\Lib\site-packages\django\core\handlers\exception.py", line 55, in inner
    response = get_response(request)
               ^^^^^^^^^^^^^^^^^^^^^
  File "C:\Users\Nazmul\AppData\Local\Programs\Python\Python311\Lib\site-packages\django\core\handlers\base.py", line 197, in _get_response
    response = wrapped_callback(request, *callback_args, **callback_kwargs)
               ^^^^^^^^^^^^^^^^^^^^^^^^^^^^^^^^^^^^^^^^^^^^^^^^^^^^^^^^^^^^
  File "C:\Users\Nazmul\AppData\Local\Programs\Python\Python311\Lib\site-packages\django\views\decorators\csrf.py", line 65, in _view_wrapper
    return view_func(request, *args, **kwargs)
           ^^^^^^^^^^^^^^^^^^^^^^^^^^^^^^^^^^^
  File "C:\Users\Nazmul\AppData\Local\Programs\Python\Python311\Lib\site-packages\django\views\generic\base.py", line 105, in view
    return self.dispatch(request, *args, **kwargs)
           ^^^^^^^^^^^^^^^^^^^^^^^^^^^^^^^^^^^^^^^
  File "C:\Users\Nazmul\AppData\Local\Programs\Python\Python311\Lib\site-packages\rest_framework\views.py", line 515, in dispatch
    response = self.handle_exception(exc)
               ^^^^^^^^^^^^^^^^^^^^^^^^^^
  File "C:\Users\Nazmul\AppData\Local\Programs\Python\Python311\Lib\site-packages\rest_framework\views.py", line 475, in handle_exception
    self.raise_uncaught_exception(exc)
  File "C:\Users\Nazmul\AppData\Local\Programs\Python\Python311\Lib\site-packages\rest_framework\views.py", line 486, in raise_uncaught_exception
    raise exc
  File "C:\Users\Nazmul\AppData\Local\Programs\Python\Python311\Lib\site-packages\rest_framework\views.py", line 503, in dispatch
    self.initial(request, *args, **kwargs)
  File "C:\Users\Nazmul\AppData\Local\Programs\Python\Python311\Lib\site-packages\rest_framework\views.py", line 420, in initial
    self.perform_authentication(request)
  File "C:\Users\Nazmul\AppData\Local\Programs\Python\Python311\Lib\site-packages\rest_framework\views.py", line 330, in perform_authentication
    request.user
  File "C:\Users\Nazmul\AppData\Local\Programs\Python\Python311\Lib\site-packages\rest_framework\request.py", line 232, in user
    self._authenticate()
  File "C:\Users\Nazmul\AppData\Local\Programs\Python\Python311\Lib\site-packages\rest_framework\request.py", line 385, in _authenticate
    user_auth_tuple = authenticator.authenticate(self)
                      ^^^^^^^^^^^^^^^^^^^^^^^^^^^^^^^^
  File "C:\Users\Nazmul\AppData\Local\Programs\Python\Python311\Lib\site-packages\rest_framework_simplejwt\authentication.py", line 51, in authenticate
    return self.get_user(validated_token), validated_token
           ^^^^^^^^^^^^^^^^^^^^^^^^^^^^^^
  File "C:\Users\Nazmul\AppData\Local\Programs\Python\Python311\Lib\site-packages\rest_framework_simplejwt\authentication.py", line 130, in get_user
    user = self.user_model.objects.get(**{api_settings.USER_ID_FIELD: user_id})
           ^^^^^^^^^^^^^^^^^^^^^^^^^^^^^^^^^^^^^^^^^^^^^^^^^^^^^^^^^^^^^^^^^^^^
  File "C:\Users\Nazmul\AppData\Local\Programs\Python\Python311\Lib\site-packages\django\db\models\manager.py", line 87, in manager_method
    return getattr(self.get_queryset(), name)(*args, **kwargs)
           ^^^^^^^^^^^^^^^^^^^^^^^^^^^^^^^^^^^^^^^^^^^^^^^^^^^
  File "C:\Users\Nazmul\AppData\Local\Programs\Python\Python311\Lib\site-packages\django\db\models\query.py", line 629, in get
    num = len(clone)
          ^^^^^^^^^^
  File "C:\Users\Nazmul\AppData\Local\Programs\Python\Python311\Lib\site-packages\django\db\models\query.py", line 366, in __len__
    self._fetch_all()
  File "C:\Users\Nazmul\AppData\Local\Programs\Python\Python311\Lib\site-packages\django\db\models\query.py", line 1949, in _fetch_all
    self._result_cache = list(self._iterable_class(self))
                         ^^^^^^^^^^^^^^^^^^^^^^^^^^^^^^^^
  File "C:\Users\Nazmul\AppData\Local\Programs\Python\Python311\Lib\site-packages\django\db\models\query.py", line 91, in __iter__
    results = compiler.execute_sql(
              ^^^^^^^^^^^^^^^^^^^^^
  File "C:\Users\Nazmul\AppData\Local\Programs\Python\Python311\Lib\site-packages\django\db\models\sql\compiler.py", line 1610, in execute_sql
    sql, params = self.as_sql()
                  ^^^^^^^^^^^^^
  File "C:\Users\Nazmul\AppData\Local\Programs\Python\Python311\Lib\site-packages\django\db\models\sql\compiler.py", line 766, in as_sql
    extra_select, order_by, group_by = self.pre_sql_setup(
                                       ^^^^^^^^^^^^^^^^^^^
  File "C:\Users\Nazmul\AppData\Local\Programs\Python\Python311\Lib\site-packages\django\db\models\sql\compiler.py", line 85, in pre_sql_setup
    self.setup_query(with_col_aliases=with_col_aliases)
  File "C:\Users\Nazmul\AppData\Local\Programs\Python\Python311\Lib\site-packages\django\db\models\sql\compiler.py", line 74, in setup_query
    self.select, self.klass_info, self.annotation_col_map = self.get_select(
                                                            ^^^^^^^^^^^^^^^^
  File "C:\Users\Nazmul\AppData\Local\Programs\Python\Python311\Lib\site-packages\django\db\models\sql\compiler.py", line 316, in get_select
    sql, params = self.compile(col)
                  ^^^^^^^^^^^^^^^^^
  File "C:\Users\Nazmul\AppData\Local\Programs\Python\Python311\Lib\site-packages\django\db\models\sql\compiler.py", line 577, in compile
    sql, params = node.as_sql(self, self.connection)
                  ^^^^^^^^^^^^^^^^^^^^^^^^^^^^^^^^^^
  File "C:\Users\Nazmul\AppData\Local\Programs\Python\Python311\Lib\site-packages\django\db\models\expressions.py", line 1305, in as_sql
    sql = ".".join(map(compiler.quote_name_unless_alias, identifiers))
          ^^^^^^^^^^^^^^^^^^^^^^^^^^^^^^^^^^^^^^^^^^^^^^^^^^^^^^^^^^^^
  File "C:\Users\Nazmul\AppData\Local\Programs\Python\Python311\Lib\site-packages\django\db\models\sql\compiler.py", line 568, in quote_name_unless_alias
    r = self.connection.ops.quote_name(name)
        ^^^^^^^^^^^^^^^^^^^^^^^^^^^^^^^^^^^^
  File "C:\Users\Nazmul\AppData\Local\Programs\Python\Python311\Lib\site-packages\django\db\backends\dummy\base.py", line 20, in complain
    raise ImproperlyConfigured(
django.core.exceptions.ImproperlyConfigured: settings.DATABASES is improperly configured. Please supply the ENGINE value. Check settings documentation for more details.
ERROR 2025-07-02 08:03:04,133 basehttp 12332 17056 "POST /api/chat/ HTTP/1.1" 500 183884
INFO 2025-07-02 08:03:14,431 autoreload 12332 19712 C:\Users\Nazmul\Desktop\chatbot\project\settings.py changed, reloading.
INFO 2025-07-02 08:03:17,411 autoreload 20936 20476 Watching for file changes with StatReloader
INFO 2025-07-02 08:03:31,741 views 20936 5592 Sending query to Gemini API: hi
INFO 2025-07-02 08:03:34,164 views 20936 5592 Chat interaction saved for user: nazmul
INFO 2025-07-02 08:03:34,173 basehttp 20936 5592 "POST /api/chat/ HTTP/1.1" 200 116
INFO 2025-07-02 08:04:40,091 views 20936 5592 Sending query to Gemini API: himel
INFO 2025-07-02 08:04:40,843 views 20936 5592 Chat interaction saved for user: nazmul
INFO 2025-07-02 08:04:40,844 basehttp 20936 5592 "POST /api/chat/ HTTP/1.1" 200 202
INFO 2025-07-02 08:06:39,407 views 20936 5592 Sending query to Gemini API: what is himel means
INFO 2025-07-02 08:06:40,132 views 20936 5592 Chat interaction saved for user: nazmul
INFO 2025-07-02 08:06:40,132 basehttp 20936 5592 "POST /api/chat/ HTTP/1.1" 200 175
INFO 2025-07-02 08:07:22,695 views 20936 5592 Sending query to Gemini API: your are worang
INFO 2025-07-02 08:07:23,585 views 20936 5592 Chat interaction saved for user: nazmul
INFO 2025-07-02 08:07:23,585 basehttp 20936 5592 "POST /api/chat/ HTTP/1.1" 200 297
INFO 2025-07-02 08:07:38,547 views 20936 5592 Sending query to Gemini API: nazmul means
INFO 2025-07-02 08:07:39,842 views 20936 5592 Chat interaction saved for user: nazmul
INFO 2025-07-02 08:07:39,850 basehttp 20936 5592 "POST /api/chat/ HTTP/1.1" 200 401
INFO 2025-07-02 08:15:08,386 autoreload 20936 20476 C:\Users\Nazmul\Desktop\chatbot\project\settings.py changed, reloading.
INFO 2025-07-02 08:15:11,539 autoreload 10544 8108 Watching for file changes with StatReloader
INFO 2025-07-02 08:15:23,551 basehttp 10544 19096 "GET / HTTP/1.1" 200 16560
INFO 2025-07-02 08:15:23,611 basehttp 10544 19096 "GET /api/chat/history/ HTTP/1.1" 200 31245
INFO 2025-07-02 08:15:27,838 views 10544 19096 Sending query to Gemini API: hello
DEBUG 2025-07-02 08:15:30,032 views 10544 19096 Raw Gemini API response: Hello there! How can I help you today?

INFO 2025-07-02 08:15:30,051 views 10544 19096 Chat interaction saved for user: nazmul
INFO 2025-07-02 08:15:30,051 basehttp 10544 19096 "POST /api/chat/ HTTP/1.1" 200 122
